Workbook
Name AuthorityFY1819: #REF!
Name AuthorityFY1920: #REF!
Name AuthorityFY2021: #REF!
Name AuthorityFY2122: #REF!
Name AuthorityFY2324: #REF!
Name AuthorityPhase0: #REF!
Name AuthorityPhaseA: #REF!
Name AuthorityPhaseBC: #REF!
Name AuthorityPhaseD: #REF!
Name AuthorityPhaseE: #REF!
Name Autorités2: #REF!
Name basis: #REF!
Name bbbbbbbbbbbbbbbbbbbb: #REF!
Name BI_4: #REF!
Name BudgetPhaseA: #REF!
Name BudgetPhaseBC: #REF!
Name BudgetPhaseD: #REF!
Name BudgetPhaseE: #REF!
Name bushmen_admin: #REF!
Name bushmen_easy: #REF!
Name bushmen_far: #REF!
Name bushmen_rate: #REF!
Name bushmen_travelrate: #REF!
Name CATEGORIES: #REF!
Name CCG: #REF!
Name CEGNAME: #REF!
Name CENAME: #REF!
Name CI_GL_Description: #REF!
Name Classifications: #REF!
Name CONT: #REF!
Name ContRates: #REF!
Name Conversion: #REF!
Name Cost_per_Pass_CCMEO: #REF!
Name Cost_per_Pass_MDA: #REF!
Name Cost_per_Pass_NGT: #REF!
Name Costing_Phases: '6 - Phase Name'!$F$13:$F$25
Name Costing_Phases: #REF!
Name Costing_Phases_PM: '6 - Phase Name'!$I$13:$I$25
Name Costing_Phases_PM: #REF!
Name CoT_admin: #REF!
Name CR: #REF!
Name dad: #REF!
Name Delay_list: #REF!
Name Department: #REF!
Name Depth: #REF!
Name Depth2: #REF!
Name Description_SST_Eng_Dev: #REF!
Name Destinations: #REF!
Name dfdsf: #REF!
Name DFED: #REF!
Name dfg: #REF!
Name DFGED: #REF!
Name dfgsd: #REF!
Name dfsd: #REF!
Name dfsdf: #REF!
Name dfsgdf: #REF!
Name DIR: #REF!
Name direction: #REF!
Name duree_campagne: #REF!
Name EBP: #REF!

Sheet Cover Page
B3: CSA-FIN-RD-0589
B4: Version Draft 1.0
B5: 46286
B8: Cost Analysis Data Requirement (CADRe)
D9: CADRe Part D - Additional Programmatic Inputs
D10: ORCA at SIR
C16: Prepared by ORCA Project Team
C17: Reviewed by [TBD]

Sheet Table of contents
A3: Table of Contents
C6: Version control | D6: 1 | E6: Change History | F6: Used to track the evolution of the baseline overtime
D7: 2 | E7: CM List | F7: List of documents (title, version, date, number) used in the costing exercise
B8: ✔️ | C8: Decompositions | D8: 3 | E8: Context : Taxon, Phylum and Design Reference Missions | F8: Provides context of this CADRe in relation to other associated CADRe. A given mission has alternate analysis scenarios (DRMs) and nearest neighbors in the same Taxon
B9: 🕒 | D9: 4 | E9: CBS x WBS = mapping to alternate taxonomy | F9: The CBS is a decomposition used by the costing team. The WBS is a decomposition used by the project team. this tab is used to ma the two for reporting purposes
B10: 🕒 | D10: 5 | E10: Organizational Breakdown Structure (OBS) | F10: The organizational breakdown structure identifies vendors, scientific teams, international partners, OGD clients and suppliers. It help specify their roles and hierarchy
B11: ✔️ | C11: Phasing and Scheduling | D11: 6 | E11: Phasing Nomenclature | F11: The costing team has prescribed names for engineering phases, and these may differ from the nameing convention of the project team. this tab help us identify what the project team uses as their naming convention
B12: ✔️ | D12: 7 | E12: Phasing durations | F12: This specifies the phase durations for each segment of time, accordnig to the costing definitions
B13: ✔️ | D13: 8 | E13: Milestone Register | F13: List of milestones (governance gates, technical reviews, contract start and end dates, and some interim dates)
B14: 🕒 | D14: 9 | E14: Gantt chart | F14: utility function that draws a gantt chart
D15: 10 | E15: Schedule Constraints and Dependencies
C16: Strategies | D16: 11 | E16: Strategy Narratives | F16: Narratives including: Procurement strategy, IP strategy, Open Data Strategy, Cyber strategy, staffing strategy, etc
D17: 12 | E17: DDDD - Dispose, Divest, Descope, Delay | F17: Phase F disposal plan, Divestment Plan (After nominal operations), mitigation plans for cost overruns and extended delays (descope and delay)
D18: 13 | E18: Procurement Plan | F18: Procurement plan is a list which includes past investments (Sunk Costs), anticipated R&D activities as well as future contracts, MOUs, grants and contributions, and other sources of cunding
D19: 14 | E19: Overhead Costs
B20: 🕒 | C20: Constants | D20: 15 | E20: Economic factors (rates, fees, etc) | F20: This is a default tab, pre-populated with economic constants, labour rates, and other commonly used rates like EBP
B21: 🕒 | D21: 16 | E21: Inflation Model | F21: The inflation model help actualize historic data into the current base year, and helps add inflation on future years. It is specific to the CBS segments, and includes a most likely value as well as a pessimistic value to sensitivity analysis
C22: Math Models | D22: 17 | E22: CERs used and compensation algorithms | F22: List of tools used, their versions and any compensation algorithms aplpied to results
D23: 18 | E23: Nearest Neighbors | F23: Description of Legacy or Similar Systems for comparison by analogy
D24: 19 | E24: Phasing Curves (Cost distribution functions)
D25: 20 | E25: Value Chain | F25: Economic model for job impact analysis
C26: Process Improvement | D26: 21 | E26: Lessons Learned | F26: Past Lessons learned considered, new lessons generated associated with Cost & Schedule Estimation

Sheet 1 - Change history
A1: ` Table of Contents
A3: 1. Version Control - Baseline Tracker
A4: Purpose: | B4: To track the baseline across time
B5: hold the major and minor releases of the baseline
B9: Change history and associated files that contain the relevant data | G9: Reserved
B10: File Number | C10: Date | D10: File Version | E10: Author | F10: Changes | G10: Parent Baseline Name | H10: Baseline ID
G11: ORCA @ PREP1 | H11: 1
G12: ORCA @ KDP-0 | H12: 2
G13: ORCA @ MDR#2 | H13: 3
G14: ORCA @ PREP2 | H14: 4
G15: ORCA @ KDP-A | H15: 5
G16: ORCA @ KDP-B | H16: 6
G17: ORCA @ PDR | H17: 7
G18: ORCA @ CDR | H18: 8
B19: CSA-FIN-RD-0591 | C19: 46286 | D19: Draft 1 | E19: MB | F19: Initial CADRe Part D baseline: schedule scenarios, dependencies, strategies and procurement plan, aligned to the CADRe Part C SIR baseline. | G19: ORCA @ SIR | H19: 9 | I19: <<--- We are here now
G20: ORCA @ KDP-E | H20: 10
G21: ORCA @ Launch (as flown) | H21: 11
G22: ORCA @ CR | H22: 12
G23: ORCA @ KDP-X | H23: 13
G24: ORCA @ end of life | H24: 14

Sheet 2 - CM 
A1: ` Table of Contents
A3: 2. Version Control - CM List - Document Tracker
A4: Purpose: | B4: this is a list of useful documents used in costing
A5: Why we are asking for this:
B6: It helps document the source of inputs used in calculations
R8: Reserved
B9: Internal ID | C9: Category | D9: Document Title | E9: Org | F9: Doc Number | G9: Doc version | H9: Doc date | I9: Phase | J9: Milestone | K9: CDRL | L9: Source | M9: Contract No | N9: LL Data ID | O9: hyperlink | P9: Comments | Q9: Used in this CADRe ? | R9: Parent Baseline
B10: 1.01 | C10: Costing Exercise | D10: ORCA CADRe Part A - Mission Description | E10: CSA | F10: ORC-CAD-A-001 | G10: Rev 1.0 | H10: 46490 | I10: Phase D | J10: Start of Nominal Operations | K10: A | L10: ORCA CM Repository | M10: ORC-CSA-001 | N10: LL-ORC-001 | O10: https://cm.orca.fake/ORC-CAD-A-001 | P10: Baseline mission description | Q10: Yes | R10: ORC-BASE-001
B11: 1.02 | C11: Costing Exercise | D11: ORCA CADRe Part B - Engineering Parameters | E11: CSA | F11: ORC-CAD-B-001 | G11: Rev 1.0 | H11: 46490 | I11: Phase D | J11: Start of Nominal Operations | K11: B | L11: ORCA CM Repository | M11: ORC-CSA-001 | N11: LL-ORC-002 | O11: https://cm.orca.fake/ORC-CAD-B-001 | P11: Engineering parameter baseline | Q11: Yes | R11: ORC-BASE-001
B12: 1.03 | C12: Costing Exercise | D12: ORCA CADRe Part C - Essential Programmatics | E12: CSA | F12: ORC-CAD-C-001 | G12: Rev 1.0 | H12: 46490 | I12: Phase D | J12: Start of Nominal Operations | K12: C | L12: ORCA CM Repository | M12: ORC-CSA-001 | N12: LL-ORC-003 | O12: https://cm.orca.fake/ORC-CAD-C-001 | P12: Programmatic baseline | Q12: Yes | R12: ORC-BASE-001
B13: 1.04 | C13: Costing Exercise | D13: ORCA CADRe Part D - More Programmatics | E13: CSA | F13: ORC-CAD-D-001 | G13: Rev 1.0 | H13: 46490 | I13: Phase D | J13: Start of Nominal Operations | K13: D | L13: ORCA CM Repository | M13: ORC-CSA-001 | N13: LL-ORC-004 | O13: https://cm.orca.fake/ORC-CAD-D-001 | P13: Current CADRe Part D baseline | Q13: Yes | R13: ORC-BASE-001
B14: 1.05 | C14: Costing Exercise | D14: ORCA PM Cost Report | E14: CSA | F14: ORC-PM-COST-001 | G14: Rev 1.0 | H14: 46490 | I14: Phase D | J14: Start of Nominal Operations | K14: - | L14: ORCA PMO | M14: ORC-CSA-001 | N14: LL-ORC-005 | O14: https://cm.orca.fake/ORC-PM-COST-001 | P14: Current cost baseline | Q14: Yes | R14: ORC-BASE-001
B15: 1.06 | C15: Costing Exercise | D15: ORCA Cost Model Verification Checklist | E15: CSA | F15: ORC-CM-VER-001 | G15: Rev 1.0 | H15: 46490 | I15: Phase D | J15: Start of Nominal Operations | K15: - | L15: ORCA PMO | M15: ORC-CSA-001 | N15: LL-ORC-006 | O15: https://cm.orca.fake/ORC-CM-VER-001 | P15: Cost model verification | Q15: Yes | R15: ORC-BASE-001
B16: 1.07 | C16: Costing Exercise | D16: ORCA Risk Cost Adjustment Memo | E16: CSA | F16: ORC-RISK-COST-001 | G16: Rev 1.0 | H16: 46490 | I16: Phase D | J16: Start of Nominal Operations | K16: - | L16: ORCA PMO | M16: ORC-CSA-001 | N16: LL-ORC-007 | O16: https://cm.orca.fake/ORC-RISK-COST-001 | P16: Risk-adjusted cost inputs | Q16: Yes | R16: ORC-BASE-001
B17: 2.01 | C17: Governance | D17: ORCA Project Charter | E17: CSA | F17: ORC-GOV-001 | G17: Rev 2.0 | H17: 45638 | I17: Phase C | J17: Critical Design Review | K17: - | L17: ORCA PMO | M17: ORC-CSA-001 | N17: LL-ORC-008 | O17: https://cm.orca.fake/ORC-GOV-001 | P17: Approved project governance baseline | Q17: Yes | R17: ORC-BASE-001
B18: 2.02 | C18: Governance | D18: ORCA KDP-E Decision Package | E18: CSA | F18: ORC-GOV-002 | G18: Rev 1.0 | H18: 46490 | I18: Phase D | J18: Start of Nominal Operations | K18: - | L18: ORCA PMO | M18: ORC-CSA-001 | N18: LL-ORC-009 | O18: https://cm.orca.fake/ORC-GOV-002 | P18: KDP-E program decision baseline | Q18: Yes | R18: ORC-KDPE-001
B19: 2.03 | C19: Governance | D19: ORCA Phase E Gate Data Package | E19: CSA | F19: ORC-GOV-003 | G19: Rev 1.0 | H19: 46490 | I19: Phase D | J19: Start of Nominal Operations | K19: - | L19: ORCA PMO | M19: ORC-CSA-001 | N19: LL-ORC-010 | O19: https://cm.orca.fake/ORC-GOV-003 | P19: Phase E evidence package | Q19: Yes | R19: ORC-KDPE-001
B20: 2.04 | C20: Governance | D20: ORCA Configuration Control Board Charter | E20: CSA | F20: ORC-GOV-004 | G20: Rev 1.0 | H20: 46289 | I20: Phase D | J20: Acceptance Review | K20: - | L20: ORCA PMO | M20: ORC-CSA-001 | N20: LL-ORC-011 | O20: https://cm.orca.fake/ORC-GOV-004 | P20: CM authority and change control | Q20: Yes | R20: ORC-BASE-001
B21: 2.05 | C21: Governance | D21: ORCA KDP-E Baseline Approval Memo | E21: CSA | F21: ORC-GOV-005 | G21: Rev 1.0 | H21: 46490 | I21: Phase D | J21: Start of Nominal Operations | K21: - | L21: ORCA PMO | M21: ORC-CSA-001 | N21: LL-ORC-012 | O21: https://cm.orca.fake/ORC-GOV-005 | P21: Configuration baseline approval | Q21: Yes | R21: ORC-KDPE-001
... B45: 9.04 | C45: Vendor Quotes | D45: Flight Computer and Avionics Procurement Estimate | E45: CSA | F45: ORC-VQ-004 | G45: Rev 1.0 | H45: 45611 | I45: Phase C | J45: Critical Design Review | K45: - | L45: ORCA Procurement | M45: ORC-CSA-001 | N45: LL-ORC-036 | O45: https://quotes.orca.fake/ORC-VQ-004 | P45: Fictional supplier estimate | Q45: Yes | R45: ORC-BASE-001

Sheet 3 - Taxon
A1: ` Table of Contents
A3: 3. Context (TAXON, Phylum , DRM)
A4: Purpose: | B4: Provides context of this CADRe in relation to other associated CADRe. A given mission has alternate analysis scenarios (DRMs) and nearest neighbors in the same Taxon
B5: The DRM is used to express different mission concepts, or different analysis options like AIS (on-off), mission class (B-C)
A8: The taxon is used to classify missions into similar neighborhoods.
A9: TAXON 1 | B9: TAXON 2 | C9: PHYLUM | D9: Generation | E9: Missions | F9: Mission Description | G9: Analysis Scenarios | H9: Analysis Scenarios desc | I9: DRM
A10: Space Mission | B10: Orbital Sustainability Missions | C10: On-Orbit Debris Removal | D10: 1 | E10: DELTARA | F10: Single-target mission that captures an inactive satellite and lowers its orbit for atmospheric re-entry. | G10: Single-Pass Sampling Scenario | I10: DRM-VAN-001
D11: 2 | E11: NEXORA | F11: Multi-target debris-removal mission using autonomous orbital transfers between inactive LEO satellites. | G11: Multi-Pass Sampling Scenario | I11: DRM-NEX-001
D12: 3 | E12: SENTRA | F12: Active debris-removal mission using a robotic capture arm to rendezvous with and deorbit inactive LEO satellites. | G12: SENTRA Baseline Mission | I12: DRM-SEN-001: Multi-target rendezvous, robotic capture, and deorbit of inactive LEO satellites
F13: Space situational awareness mission | G13: Option 1 | H13: MDA concept at Phase 0
G14: Option 2 | H14: Airbus concept at Phase 0
G15: Option 3 | H15: Boeing Mission Concept at Phase 0
G16: Option 4 | H16: PPP option by Company X
G17: Baseline at KDP-B | H17: Comdev is the mission baseline starting at Phase B
C18: On_orbit Servicing | D18: 1 | E18: VANTERA | F18: Robotic inspection of inactive LEO spacecraft. | G18: Inspection Scenario
D19: 2 | E19: ORVEX | F19: Robotic capture and servicing of cooperative spacecraft. | G19: Servicing Scenario
H20: Remote sensing of the Enceladus plume and surface. | I20: Inspection Scenario
H21: In-situ sampling and analysis of plume ejecta. | I21: Servicing Scenario
A22: Space Mission | B22: Deep Space Science Missions | C22: Outer-Planet In-Situ Instrument Missions | D22: 1 | E22: LUMEN | F22: CSA-led space telescope instrument contribution to a partner-agency observatory mission. | G22: LUMEN Baseline Mission | I22: DRM-LUM-001
D23: 2 | E23: BOREALIS | F23: CSA-led remote-sensing instrument contribution to a partner-agency deep-space mission. | G23: Borealis Baseline Mission | I23: DRM-BOR-001
D24: 3 | E24: ORCA | F24: CSA-led instrument suite (ice-penetrating radar, mass spectrometer and sampling arm) hosted on the NEREID orbiter (NASA-led, ESA-contributed platform) to transit Enceladus's plume and characterize its composition and sub-surface ocean chemistry. | G24: ORCA Baseline Mission | I24: DRM-ORC-001: Enceladus plume transit, in-situ sampling, and sub-surface ocean chemistry characterization
C33: On-Orbit Servicing | D33: 1 | E33: VANTERA | F33: Robotic inspection of inactive LEO spacecraft. | G33: Inspection Scenario | I33: DRM-VAN-001
D34: 2 | E34: ORVEX | F34: Robotic capture and servicing of cooperative spacecraft. | G34: Servicing Scenario | I34: DRM-ORV-001

Sheet 4- WBS Mapping
A1: 4. CBS to WBS Traceability Table — ORCA
A2: Purpose: | B2: The ORCA WBS translates the project CBS into the mission team's planning and reporting structure, covering the NEREID Orbiter, instrument accommodation payload, launch, ground segment, integration, and mission operations.
A4: WBS | B4: WBS Element | C4: Phase A | D4: Phase B/C | E4: MAIT | F4: SAIT | G4: LEOP | H4: Phase E/X
A5: 1 | B5: ORCA Mission Program | C5: 1.1, 1.2 | D5: 1.1, 1.2, 1.3 | E5: 1.1 | F5: 1.1 | G5: 1.1 | H5: 1.1
A6: 1.1 | B6: Project Management & Mission Control | C6: 1.1 | D6: 1.1 | E6: 1.1 | F6: 1.1 | G6: 1.1 | H6: 1.1
A7: 1.1.1 | B7: Project Management & Controls | C7: 1.1.1 | D7: 1.1.1 | E7: 1.1.1 | F7: 1.1.1 | G7: 1.1.1 | H7: 1.1.1
A8: 1.1.2 | B8: Cost, Schedule & Configuration Management | C8: 1.1.2 | D8: 1.1.2 | E8: 1.1.2 | F8: 1.1.2 | G8: 1.1.2 | H8: 1.1.2
A9: 1.1.3 | B9: Reviews, Governance & Mission Reporting | C9: 1.1.3 | D9: 1.1.3 | E9: 1.1.3 | F9: 1.1.3 | G9: 1.1.3 | H9: 1.1.3
A10: 1.2 | B10: Safety & Mission Assurance | C10: 1.2 | D10: 1.2 | E10: 1.2 | F10: 1.2 | G10: 1.2 | H10: 1.2
A11: 1.3 | B11: Host Orbiter Interface & Accommodation (Partner-Provided Platform) | C11: 1.3 | D11: 1.3 | E11: 1.3 | F11: 1.3 | G11: 1.3 | H11: 1.3
A12: 1.3.1 | B12: Power Interface & Energy Budget Coordination | C12: 1.3.1 | D12: 1.3.1 | E12: 1.3.1 | F12: 1.3.1 | G12: 1.3.1 | H12: 1.3.1
A13: 1.3.2 | B13: Pointing & Accommodation Requirements | C13: 1.3.2 | D13: 1.3.2 | E13: 1.3.2 | F13: 1.3.2 | G13: 1.3.2 | H13: 1.3.2
A14: 1.3.3 | B14: Command & Data Handling Interface | C14: 1.3.3 | D14: 1.3.3 | E14: 1.3.3 | F14: 1.3.3 | G14: 1.3.3 | H14: 1.3.3
A15: 1.3.4 | B15: Communications Relay Interface | C15: 1.3.4 | D15: 1.3.4 | E15: 1.3.4 | F15: 1.3.4 | G15: 1.3.4 | H15: 1.3.4
... A21: 1.4.3 | B21: Mass Spectrometer & Instrument Electronics | C21: 1.4.3 | D21: 1.4.3 | E21: 1.4.3 | F21: 1.4.3 | G21: 1.4.3 | H21: 1.4.3
A22: 1.5 | B22: Launch Support (Partner-Procured) | C22: 1.5 | D22: 1.5 | E22: 1.5 | F22: 1.5
A23: 1.5.1 | B23: Instrument Suite Launch Readiness | D23: 1.5.1 | E23: 1.5.1 | F23: 1.5.1
A24: 1.5.2 | B24: Launch Campaign Support | E24: 1.5.2 | F24: 1.5.2 | G24: 1.5.2
A25: 1.6 | B25: Ground Segment | C25: 1.6 | D25: 1.6 | E25: 1.6 | F25: 1.6 | G25: 1.6 | H25: 1.6
A26: 1.6.1 | B26: Mission Control & Telemetry | C26: 1.6.1 | D26: 1.6.1 | E26: 1.6.1 | F26: 1.6.1 | G26: 1.6.1 | H26: 1.6.1
A27: 1.6.2 | B27: Mission Planning & Science Data Database | C27: 1.6.2 | D27: 1.6.2 | E27: 1.6.2 | F27: 1.6.2 | G27: 1.6.2 | H27: 1.6.2
A28: 1.7 | B28: Mission Operations | C28: 1.7 | D28: 1.7 | E28: 1.7 | F28: 1.7 | G28: 1.7 | H28: 1.7
A29: 1.7.1 | B29: Plume Transit & Sampling Operations | D29: 1.7.1 | E29: 1.7.1 | F29: 1.7.1 | G29: 1.7.1 | H29: 1.7.1
A30: 1.7.2 | B30: Sample Acquisition & Science Data Operations | E30: 1.7.2 | F30: 1.7.2 | G30: 1.7.2 | H30: 1.7.2
A31: 1.8 | B31: System Integration, Assembly, Test & Verification | D31: 1.8 | E31: 1.8 | F31: 1.8 | G31: 1.8
A32: 1.8.1 | B32: Engineering Model Integration & Test | D32: 1.8.1 | E32: 1.8.1
A33: 1.8.2 | B33: Qualification & Environmental Testing | D33: 1.8.2 | E33: 1.8.2 | F33: 1.8.2
A34: 1.8.3 | B34: Flight Acceptance & End-to-End Testing | F34: 1.8.3 | G34: 1.8.3
A35: 1.9 | B35: Commissioning | G35: 1.9 | H35: 1.9
A36: 1.9.1 | B36: Host Orbiter Interface Commissioning | G36: 1.9.1 | H36: 1.9.1
A37: 1.9.2 | B37: Instrument Suite Commissioning | G37: 1.9.2 | H37: 1.9.2

Sheet 4d - CBS in JS format
A1: ` Table of Contents
A3: 4d. CBS (as self referencing list) for use as a javascript array
A4: Why we we asking:
B5: this page is auto-generated and used for drawing it out
E6: Self referencing list for dtree
A8: UID | B8: Parent ID | C8: Level | D8: Node Name | E8: CBS Code | F8: Depth | G8: Icon | H8: Notes | J8: Javascript Code | N8: Depth
A9: 1 | B9: -1 | C9: 1 | D9: Space Missions | F9: Taxon 1 | G9: Box.png | J9: ="datatable["&A9-1&"] = new Array(""" & A9 &""",""" & B9 &""",""" & D9 & """,""" & C9&""","""&""&G9&""");" -> datatable[0] = new Array("1","-1","Space Missions","1","Box.png"); | N9: Taxon 1
A10: 2 | B10: =A9 -> 1 | C10: 2 | D10: EO SAR Missions | F10: Taxon 2 | G10: EO.png | J10: ="datatable["&A10-1&"] = new Array(""" & A10 &""",""" & B10 &""",""" & D10 & """,""" & C10&""","""&""&G10&""");" -> datatable[1] = new Array("2","1","EO SAR Missions","2","EO.png"); | N10: Taxon 2
A11: =A10+1 -> 3 | B11: =A10 -> 2 | C11: 3 | D11: Radarsat Portfolio | F11: Phylum | G11: Pouch.png | J11: ="datatable["&A11-1&"] = new Array(""" & A11 &""",""" & B11 &""",""" & D11 & """,""" & C11&""","""&""&G11&""");" -> datatable[2] = new Array("3","2","Radarsat Portfolio","3","Pouch.png"); | N11: Phylum
A12: =A11+1 -> 4 | B12: =A$6 -> 0 | C12: 4 | D12: Radarsat 1 | F12: Mission | G12: Satellite.png | J12: ="datatable["&A12-1&"] = new Array(""" & A12 &""",""" & B12 &""",""" & D12 & """,""" & C12&""","""&""&G12&""");" -> datatable[3] = new Array("4","0","Radarsat 1","4","Satellite.png"); | N12: Mission
A13: =A12+1 -> 5 | B13: =A$6 -> 0 | C13: 4 | D13: Radarsat 2 | F13: Mission | G13: Satellite.png | J13: ="datatable["&A13-1&"] = new Array(""" & A13 &""",""" & B13 &""",""" & D13 & """,""" & C13&""","""&""&G13&""");" -> datatable[4] = new Array("5","0","Radarsat 2","4","Satellite.png"); | N13: Design Reference Mission
A14: =A13+1 -> 6 | B14: =A$6 -> 0 | C14: 4 | D14: Radarsat Constellation Mission | F14: Mission | G14: Satellite.png | J14: ="datatable["&A14-1&"] = new Array(""" & A14 &""",""" & B14 &""",""" & D14 & """,""" & C14&""","""&""&G14&""");" -> datatable[5] = new Array("6","0","Radarsat Constellation Mission","4","Satellite.png"); | N14: Segment
A15: =A14+1 -> 7 | B15: =A$6 -> 0 | C15: 4 | D15: Radarsat+ Replenishment | E15: 1 | F15: Mission | G15: Satellite.png | J15: ="datatable["&A15-1&"] = new Array(""" & A15 &""",""" & B15 &""",""" & D15 & """,""" & C15&""","""&""&G15&""");" -> datatable[6] = new Array("7","0","Radarsat+ Replenishment","4","Satellite.png"); | N15: System of Systems
A16: =A15+1 -> 8 | B16: =A$6 -> 0 | C16: 4 | D16: Radarsat+ Next Generation | F16: Mission | G16: Satellite.png | J16: ="datatable["&A16-1&"] = new Array(""" & A16 &""",""" & B16 &""",""" & D16 & """,""" & C16&""","""&""&G16&""");" -> datatable[7] = new Array("8","0","Radarsat+ Next Generation","4","Satellite.png"); | N16: System
A17: =A16+1 -> 9 | B17: =A$10 -> 2 | C17: 5 | D17: Analysis Scenario 1: RCM Proxy | F17: Design Reference Mission | G17: Scenario.png | J17: ="datatable["&A17-1&"] = new Array(""" & A17 &""",""" & B17 &""",""" & D17 & """,""" & C17&""","""&""&G17&""");" -> datatable[8] = new Array("9","2","Analysis Scenario 1: RCM Proxy","5","Scenario.png"); | N17: Subsystem
A18: =A17+1 -> 10 | B18: =A$10 -> 2 | C18: 5 | D18: Analysis Scenario 2: RCM+ | F18: Design Reference Mission | G18: Scenario.png | J18: ="datatable["&A18-1&"] = new Array(""" & A18 &""",""" & B18 &""",""" & D18 & """,""" & C18&""","""&""&G18&""");" -> datatable[9] = new Array("10","2","Analysis Scenario 2: RCM+","5","Scenario.png"); | N18: Assembly
A19: =A18+1 -> 11 | B19: =A$10 -> 2 | C19: 5 | D19: Analysis Scenario 3: Airbus concept | F19: Design Reference Mission | G19: Scenario.png | J19: ="datatable["&A19-1&"] = new Array(""" & A19 &""",""" & B19 &""",""" & D19 & """,""" & C19&""","""&""&G19&""");" -> datatable[10] = new Array("11","2","Analysis Scenario 3: Airbus concept","5","Scenario.png"); | N19: Component
A20: =A19+1 -> 12 | B20: =A$10 -> 2 | C20: 5 | D20: Analysis Scenario 4: MDA Chorus Data Buy | F20: Design Reference Mission | G20: Scenario.png | J20: ="datatable["&A20-1&"] = new Array(""" & A20 &""",""" & B20 &""",""" & D20 & """,""" & C20&""","""&""&G20&""");" -> datatable[11] = new Array("12","2","Analysis Scenario 4: MDA Chorus Data Buy","5","Scenario.png");
A21: =A20+1 -> 13 | B21: =A$10 -> 2 | C21: 5 | D21: Analysis Scenario 5: MDA Chorus+ | F21: Design Reference Mission | G21: Scenario.png | J21: ="datatable["&A21-1&"] = new Array(""" & A21 &""",""" & B21 &""",""" & D21 & """,""" & C21&""","""&""&G21&""");" -> datatable[12] = new Array("13","2","Analysis Scenario 5: MDA Chorus+","5","Scenario.png");
A22: =A21+1 -> 14 | B22: =A$10 -> 2 | C22: 5 | D22: Analysis Scenario 6: Airbus Sentinel 2 | F22: Design Reference Mission | G22: Scenario.png | J22: ="datatable["&A22-1&"] = new Array(""" & A22 &""",""" & B22 &""",""" & D22 & """,""" & C22&""","""&""&G22&""");" -> datatable[13] = new Array("14","2","Analysis Scenario 6: Airbus Sentinel 2","5","Scenario.png");
A23: =A22+1 -> 15 | B23: =A$16 -> 8 | C23: 6 | D23: Government Overhead and Oversight | E23: 1.1 | F23: Segment | G23: Government.png | H23: This WBS includes all CSA Oversight, OGD salaries, and basic overhead for the care and maintenance of CSA staff | J23: ="datatable["&A23-1&"] = new Array(""" & A23 &""",""" & B23 &""",""" & D23 & """,""" & C23&""","""&""&G23&""");" -> datatable[14] = new Array("15","8","Government Overhead and Oversight","6","Government.png");
A24: =A23+1 -> 16 | B24: =A$16 -> 8 | C24: 6 | D24: Space Segment | E24: 1.2 | F24: Segment | G24: Satellite.png | H24: The Space Segment includes things we launch into space | J24: ="datatable["&A24-1&"] = new Array(""" & A24 &""",""" & B24 &""",""" & D24 & """,""" & C24&""","""&""&G24&""");" -> datatable[15] = new Array("16","8","Space Segment","6","Satellite.png");
A25: =A24+1 -> 17 | B25: =A$16 -> 8 | C25: 6 | D25: Launch Segment | E25: 1.3 | F25: Segment | G25: Rocket.png | H25: The launch segment includes the launch vehicle and seom support services | J25: ="datatable["&A25-1&"] = new Array(""" & A25 &""",""" & B25 &""",""" & D25 & """,""" & C25&""","""&""&G25&""");" -> datatable[16] = new Array("17","8","Launch Segment","6","Rocket.png");
A26: =A25+1 -> 18 | B26: =A$16 -> 8 | C26: 6 | D26: Ground Segment | E26: 1.4 | F26: Segment | G26: Facility.png | H26: The ground segment includes the planning desgin and development of the GS, but not the Ops | J26: ="datatable["&A26-1&"] = new Array(""" & A26 &""",""" & B26 &""",""" & D26 & """,""" & C26&""","""&""&G26&""");" -> datatable[17] = new Array("18","8","Ground Segment","6","Facility.png");
A27: =A26+1 -> 19 | B27: =A$16 -> 8 | C27: 6 | D27: Ops Segment | E27: 1.5 | F27: Segment | G27: Ops.png | H27: Ops includes SatOps, Mission Ops, Science Ops - typically contracts | J27: ="datatable["&A27-1&"] = new Array(""" & A27 &""",""" & B27 &""",""" & D27 & """,""" & C27&""","""&""&G27&""");" -> datatable[18] = new Array("19","8","Ops Segment","6","Ops.png");
A28: =A27+1 -> 20 | B28: =A$16 -> 8 | C28: 6 | D28: Science Segment | E28: 1.6 | F28: Segment | G28: Science.png | H28: Typically G&C | J28: ="datatable["&A28-1&"] = new Array(""" & A28 &""",""" & B28 &""",""" & D28 & """,""" & C28&""","""&""&G28&""");" -> datatable[19] = new Array("20","8","Science Segment","6","Science.png");
A29: =A28+1 -> 21 | B29: =A$18 -> 10 | C29: 7 | D29: Gov't Oversight (Salaries and EBP) | E29: 1.1.1 | F29: System of Systems | G29: Government.png | J29: ="datatable["&A29-1&"] = new Array(""" & A29 &""",""" & B29 &""",""" & D29 & """,""" & C29&""","""&""&G29&""");" -> datatable[20] = new Array("21","10","Gov't Oversight (Salaries and EBP)","7","Government.png");
A30: =A29+1 -> 22 | B30: =A$18 -> 10 | C30: 7 | D30: Government Overhead | E30: 1.1.2 | F30: System of Systems | G30: Government.png | J30: ="datatable["&A30-1&"] = new Array(""" & A30 &""",""" & B30 &""",""" & D30 & """,""" & C30&""","""&""&G30&""");" -> datatable[21] = new Array("22","10","Government Overhead","7","Government.png");
A31: =A30+1 -> 23 | B31: =A29 -> 21 | C31: 8 | D31: CSA Oversight | E31: 1.1.1.1 | F31: System | G31: Government.png | J31: ="datatable["&A31-1&"] = new Array(""" & A31 &""",""" & B31 &""",""" & D31 & """,""" & C31&""","""&""&G31&""");" -> datatable[22] = new Array("23","21","CSA Oversight","8","Government.png");
A32: =A31+1 -> 24 | B32: =A29 -> 21 | C32: 8 | D32: OGD Oversight | E32: 1.1.1.2 | F32: System | G32: Government.png | J32: ="datatable["&A32-1&"] = new Array(""" & A32 &""",""" & B32 &""",""" & D32 & """,""" & C32&""","""&""&G32&""");" -> datatable[23] = new Array("24","21","OGD Oversight","8","Government.png");
A33: =A32+1 -> 25 | B33: =A31 -> 23 | C33: 9 | D33: CSA Project Team | E33: 1.1.1.1.1 | F33: Subsystem | G33: Government.png | H33: This CBS contains all salaries associated with the RAM of the Project team | J33: ="datatable["&A33-1&"] = new Array(""" & A33 &""",""" & B33 &""",""" & D33 & """,""" & C33&""","""&""&G33&""");" -> datatable[24] = new Array("25","23","CSA Project Team","9","Government.png");
A34: =A33+1 -> 26 | B34: =A31 -> 23 | C34: 9 | D34: CSA Internal Services | E34: 1.1.1.1.2 | F34: Subsystem | G34: Government.png | H34: This CBS contains all salaries associated with CSA internal services (finance, HR, audit, eval, policy, Executives, IM, IT, contracts, shipping, etc) | J34: ="datatable["&A34-1&"] = new Array(""" & A34 &""",""" & B34 &""",""" & D34 & """,""" & C34&""","""&""&G34&""");" -> datatable[25] = new Array("26","23","CSA Internal Services","9","Government.png");
A35: =A34+1 -> 27 | B35: =A32 -> 24 | C35: 9 | D35: OGD Internal Services by MOU | E35: 1.1.1.2.1 | F35: Subsystem | G35: Government.png | J35: ="datatable["&A35-1&"] = new Array(""" & A35 &""",""" & B35 &""",""" & D35 & """,""" & C35&""","""&""&G35&""");" -> datatable[26] = new Array("27","24","OGD Internal Services by MOU","9","Government.png");
A36: =A35+1 -> 28 | B36: =A32 -> 24 | C36: 9 | D36: OGD User Departments by MOU (RAM portion) | E36: 1.1.1.2.2 | F36: Subsystem | G36: Government.png | J36: ="datatable["&A36-1&"] = new Array(""" & A36 &""",""" & B36 &""",""" & D36 & """,""" & C36&""","""&""&G36&""");" -> datatable[27] = new Array("28","24","OGD User Departments by MOU (RAM portion)","9","Government.png");
A37: =A36+1 -> 29 | B37: =A$29 -> 21 | C37: 10 | D37: Shared Services | E37: 1.1.1.2.1.1 | F37: Assembly | G37: Government.png | J37: ="datatable["&A37-1&"] = new Array(""" & A37 &""",""" & B37 &""",""" & D37 & """,""" & C37&""","""&""&G37&""");" -> datatable[28] = new Array("29","21","Shared Services","10","Government.png");
A38: =A37+1 -> 30 | B38: =A$29 -> 21 | C38: 10 | D38: SPAC | E38: 1.1.1.2.1.2 | F38: Assembly | G38: Government.png | J38: ="datatable["&A38-1&"] = new Array(""" & A38 &""",""" & B38 &""",""" & D38 & """,""" & C38&""","""&""&G38&""");" -> datatable[29] = new Array("30","21","SPAC","10","Government.png");
A39: =A38+1 -> 31 | B39: =A$29 -> 21 | C39: 10 | D39: Justice Canada | E39: 1.1.1.2.1.3 | F39: Assembly | G39: Government.png | J39: ="datatable["&A39-1&"] = new Array(""" & A39 &""",""" & B39 &""",""" & D39 & """,""" & C39&""","""&""&G39&""");" -> datatable[30] = new Array("31","21","Justice Canada","10","Government.png");
A40: =A39+1 -> 32 | B40: =A$31 -> 23 | C40: 10 | D40: ECCC | E40: 1.1.1.2.2.1 | F40: Assembly | G40: Government.png | J40: ="datatable["&A40-1&"] = new Array(""" & A40 &""",""" & B40 &""",""" & D40 & """,""" & C40&""","""&""&G40&""");" -> datatable[31] = new Array("32","23","ECCC","10","Government.png");
A41: =A40+1 -> 33 | B41: =A$31 -> 23 | C41: 10 | D41: NRCAN | E41: 1.1.1.2.2.2 | F41: Assembly | G41: Government.png | J41: ="datatable["&A41-1&"] = new Array(""" & A41 &""",""" & B41 &""",""" & D41 & """,""" & C41&""","""&""&G41&""");" -> datatable[32] = new Array("33","23","NRCAN","10","Government.png");
A42: =A41+1 -> 34 | B42: =A$31 -> 23 | C42: 10 | D42: DND | E42: 1.1.1.2.2.3 | F42: Assembly | G42: Government.png | J42: ="datatable["&A42-1&"] = new Array(""" & A42 &""",""" & B42 &""",""" & D42 & """,""" & C42&""","""&""&G42&""");" -> datatable[33] = new Array("34","23","DND","10","Government.png");
...

Sheet 5- OBS
A1: ` Table of Contents
A3: 5. OBS
A4: Purpose: | B4: The organizational breakdown structure identifies vendors, scientific teams, international partners, OGD clients and suppliers. It help specify their roles and hierarchy
A5: Why we are asking for this:
B6: This information helps us understand the procurement strategy.
B7: It also helps map SAP claims against cost elements
A10: Type | B10: Sub-Type | C10: Name | D10: Description | E10: Cost sharing Provisions, who pays? | F10: How are WPD defined? | G10: Oversight | H10: Overhead | I10: Mission Level SEITPM | J10: Space Segment | K10: Launch Segment | L10: Ground Segment | M10: Ops Segment | N10: Science Segment
A11: Government | B11: Mission Owner / Project Office | C11: Canadian Orbital Mission Directorate (COMD) | D11: Fictional government organization representing the ORCA mission owner and program authority. | E11: Government mission appropriation | F11: Mission workplan / SOW | G11: x | H11: x | I11: x
A12: Industry | B12: Prime Space Systems Integrator | C12: Asterion Orbital Integration Ltd. | D12: Fictional prime contractor supporting spacecraft-level integration, verification, and technical coordination. | E12: CSA-style fiscal framework | F12: Contract SOW / CWBS | I12: x | J12: x
A13: Industry | B13: Radar Subsystem Supplier | C13: Northstar Orbital Technologies | D13: Fictional supplier providing the ice-penetrating radar subsystem for ORCA. | E13: Contract funding | F13: Contract SOW / CWBS | I13: x | J13: x
A14: Industry | B14: Sampling Arm Supplier | C14: Aetheris Space Robotics | D14: Fictional supplier providing the sampling arm, end-effector, actuators, and sample-handling mechanisms. | E14: Contract funding | F14: Contract SOW / CWBS | I14: x | J14: x
A15: Industry | B15: Avionics Supplier | C15: Polarion Avionics Corporation | D15: Fictional supplier providing flight-computing, payload electronics, and avionics support. | E15: Contract funding | F15: Contract SOW / CWBS | I15: x | J15: x
A16: Industry | B16: Context Imaging Supplier | C16: Borealis Vision Systems | D16: Fictional supplier providing plume-context imaging cameras and optical calibration equipment. | E16: Contract funding | F16: Contract SOW / CWBS | I16: x | J16: x
A17: Industry | B17: Communications Supplier | C17: Canterra Space Communications | D17: Fictional supplier providing instrument command & data-handling electronics and data-interface hardware to the NEREID orbiter. | E17: Contract funding | F17: Contract SOW / CWBS | I17: x | K17: x | L17: x
A18: Industry | B18: Thermal & Structures Supplier | C18: Arcturon Space Structures | D18: Fictional supplier supporting spacecraft structures, thermal hardware, and payload mounting interfaces. | E18: Contract funding | F18: Contract SOW / CWBS | I18: x | J18: x
A19: Industry | B19: Launch Coordination (Partner-Procured) | C19: Peregrine Launch Services | D19: Fictional launch-campaign coordination role; the launch vehicle and services are procured by the partner agency (NASA). | E19: Launch services contract | F19: Launch SOW / ICD | K19: x
A20: Industry | B20: Ground Systems Supplier | C20: Meridian Ground Technologies | D20: Fictional supplier providing mission-control interfaces, telemetry processing, and ground-system equipment. | E20: Contract funding | F20: Ground SOW / ICD | K20: x | M20: x
A22: Academia | B22: Orbital Mechanics Team | C22: Northern Institute of Space Engineering | D22: Fictional university team supporting trajectory analysis, orbital mechanics, and plume-transit navigation research. | E22: Research agreement | F22: Research SOW / workplan | M22: x | N22: x
A23: Academia | B23: Robotics Research Team | C23: Laurentia University of Aerospace Technology | D23: Fictional university team supporting sampling-arm dynamics, end-effector testing, and sample-acquisition simulations. | E23: Research agreement | F23: Research SOW / test plan | I23: x | L23: x | M23: x
A24: Academia | B24: Space Environment Team | C24: Boreal Technical University | D24: Fictional university team supporting deep-space radiation-environment analysis and mission sustainability studies. | E24: Research agreement | F24: Research SOW / workplan | M24: x | N24: x
A26: Int'l partners | B26: European Technical Partner | C26: ESA | D26: International partner (ESA) contributing to the host orbiter and providing plume-transit trajectory analysis support. | E26: Partner contribution | F26: MOU / PIP | G26: x | H26: x | I26: x | J26: x | L26: x | M26: x | N26: x
A27: Int'l partners | B27: American Host-Platform Partner | C27: NASA | D27: International partner (NASA) providing and operating the NEREID orbiter host platform, including launch. | E27: Partner contribution | F27: MOU / PIP | G27: x | H27: x | I27: x | J27: x | M27: x | N27: x
A29: Government | B29: Space Environment OGD | C29: Canadian Orbital Safety Directorate (COSD) | D29: Fictional government organization supporting export-control compliance, planetary-protection oversight, and deep-space mission assurance. | E29: Government service | F29: MOU / service agreement | G29: x | I29: x | L29: x | M29: x
A30: Government | B30: Space Weather OGD | C30: Canadian Space Environment Office (CSEO) | D30: Fictional government organization providing space-weather and orbital-environment information. | E30: Government service | F30: MOU / service agreement | G30: x | I30: x | L30: x | M30: x
A31: Government | B31: Technical Assurance OGD | C31: National Aerospace Research Directorate (NARD) | D31: Fictional government organization providing independent engineering review, testing support, and technical assurance. | E31: Government service | F31: MOU / workplan | G31: x | I31: x | J31: x | L31: x | M31: x

Sheet 6 - Phase Name
A1: ` Table of Contents
A3: 7 - Phasing Nomenclature | I3: What do you call your phases?
A4: Why we we asking:
B5: 1. To normalize the naming convention across all investments.
B6: 2. Math Models are based on Costing Sub-Phase.
B7: 3. We want to output results in your naming convention and scope.
B10: Based on IGMF rev E | F10: Based on CSA-FIN-RPT-0072
A11: Phasing according to | E11: Phasing according to | I11: Phasing according to
A12: EPMO | E12: Costing | I12: PM
E13: PREP | F13: PREP 1 | G13: Prototyping Activities (before Gate 1)
A14: Pre-Project | B14: Option Analysis & Planning Phase | C14: Pre-Phase 0 | F14: PREP 2 | G14: Prototyping Activities (during Phase 0/A)
C15: Phase 0 | E15: Phase 0/A | F15: Phase 0 | G15: Concept & Feasibility | I15: Phase 0
A16: Project | B16: Definition Phase | C16: Detailed Project Requirements | F16: Phase A | G16: Mission Requirements | I16: Phase A
C17: Preliminary Definition | E17: Phase B/C | F17: Phase B | G17: Preliminary Design | I17: Phase B
C18: Detailed Definition | F18: Phase C | G18: Detailed Design | I18: Phase C
B19: Implementation Phase | C19: Implementation | E19: Phase D | F19: MAIT | G19: Manufacturing, Assembly, Integration and Test of Canadian Subsystems and Components | I19: Phase D
F20: SAIT | G20: Spacecraft Level Assembly, Test | I20: Phase D
F21: LEOP | G21: Lauch and early operations | I21: Phase D
A22: Post-Project | B22: Post-Implementation Phase | C22: Operations & Disposal | E22: Phase E | F22: Phase E | G22: Nominal Operations (per design life) | I22: Phase E
E23: Phase E (EXT) | F23: Phase X | G23: Extended operations (mission extension)
E24: Phase F | F24: Phase F | G24: Disposal (incl. post-mortem audit reports) | I24: Phase F
E25: Phase G | F25: Phase G | G25: Post-Mortem science utilization

Sheet 7 - Phase Durations
A1: ` Table of Contents
A3: 7b - Phasing Durations
A4: Why we we asking:
B5: 1. Durations affect Govt Salaries calculations
B6: 2. Durations affect Parametric estimates for Space segment, ground segment, ops
B7: 3. Schedule Scenarios are inputs to sensitivity analysis
B9: Schedule Scenario ID | C9: 1 | M9: Click to draw
B10: Scenario Name | C10: ORCA Nominal / Baseline Schedule
B11: Scenario Description | C11: Baseline ORCA schedule used for primary planning, salary calculations and parametric estimation.
B12: Rationale | C12: Uses the ORCA Phase 0 through Phase X dates established in CADRe Part C (§7 Phase Durations).
B13: Source Doc | C13: ORCA CADRe Part A — Project Phase Schedule
B15: Phase | C15: Expected Start | D15: Expected End | E15: Total D | F15: Total M | G15: 2020 | H15: 2021 | I15: 2022 | J15: 2023 | K15: 2024 | L15: 2025 | M15: 2026 | N15: 2027 | O15: 2028 | P15: 2029 | Q15: 2030 | R15: 2031 | S15: 2032 | T15: 2033 | U15: 2034 | V15: 2035 | W15: 2036 | X15: 2037 | Y15: 2038 | Z15: 2039 | AA15: 2040 | AB15: 2041 | AC15: 2042 | AD15: 2043 | AE15: 2044 | AF15: 2045 | AG15: 2046 | AH15: 2047 | AI15: 2048 | AJ15: 2049 | AK15: 2050 | AL15: 2051 | AM15: 2052 | AN15: 2053 | AO15: 2054 | AP15: 2055 | AQ15: 2056 | AR15: 2057 | AS15: 2058 | AT15: 2059 | AU15: 2060 | AV15: 2061 | AW15: 2062 | AX15: 2063 | AY15: 2064 | AZ15: 2065 | BA15: 2066 | BB15: 2067 | BC15: 2068 | BD15: 2069 | BE15: 2070 | BF15: 2071 | BG15: 2072 | BH15: 2073 | BI15: 2074 | BJ15: 2075 | BK15: 2076 | BL15: 2077 | BM15: 2078 | BN15: 2079 | BO15: 2080 | BP15: 2081 | BQ15: 2082 | BR15: 2083 | BS15: 2084 | BT15: 2085 | BU15: 2086 | BV15: 2087 | BW15: 2088 | BX15: 2089 | BY15: 2090 | BZ15: 2091 | CA15: 2092 | CB15: 2093
A16: Phase 0 | B16: 46023 | C16: 46752 | D16: 730 | E16: 24 | F16: 9.9 | G16: 0 | H16: 0 | I16: 0 | J16: 0 | K16: 0 | L16: 0 | M16: 3 | N16: 12 | O16: 9 | P16: 0 | Q16: 0 | R16: 0 | S16: 0 | T16: 0 | U16: 0 | V16: 0 | W16: 0 | X16: 0 | Y16: 0 | Z16: 0 | AA16: 0 | AB16: 0 | AC16: 0 | AD16: 0 | AE16: 0 | AF16: 0 | AG16: 0 | AH16: 0 | AI16: 0 | AJ16: 0 | AK16: 0 | AL16: 0 | AM16: 0 | AN16: 0 | AO16: 0 | AP16: 0 | AQ16: 0 | AR16: 0 | AS16: 0 | AT16: 0 | AU16: 0 | AV16: 0 | AW16: 0 | AX16: 0 | AY16: 0 | AZ16: 0 | BA16: 0 | BB16: 0 | BC16: 0 | BD16: 0 | BE16: 0 | BF16: 0 | BG16: 0 | BH16: 0 | BI16: 0 | BJ16: 0 | BK16: 0 | BL16: 0 | BM16: 0 | BN16: 0 | BO16: 0 | BP16: 0 | BQ16: 0 | BR16: 0 | BS16: 0 | BT16: 0 | BU16: 0 | BV16: 0 | BW16: 0 | BX16: 0 | BY16: 0 | BZ16: 0 | CA16: 0 | CB16: 0
A17: Phase A | B17: 46753 | C17: 47483 | D17: 731 | E17: 24 | F17: 10.2 | G17: 0 | H17: 0 | I17: 0 | J17: 0 | K17: 0 | L17: 0 | M17: 0 | N17: 0 | O17: 3 | P17: 12 | Q17: 9 | R17: 0 | S17: 0 | T17: 0 | U17: 0 | V17: 0 | W17: 0 | X17: 0 | Y17: 0 | Z17: 0 | AA17: 0 | AB17: 0 | AC17: 0 | AD17: 0 | AE17: 0 | AF17: 0 | AG17: 0 | AH17: 0 | AI17: 0 | AJ17: 0 | AK17: 0 | AL17: 0 | AM17: 0 | AN17: 0 | AO17: 0 | AP17: 0 | AQ17: 0 | AR17: 0 | AS17: 0 | AT17: 0 | AU17: 0 | AV17: 0 | AW17: 0 | AX17: 0 | AY17: 0 | AZ17: 0 | BA17: 0 | BB17: 0 | BC17: 0 | BD17: 0 | BE17: 0 | BF17: 0 | BG17: 0 | BH17: 0 | BI17: 0 | BJ17: 0 | BK17: 0 | BL17: 0 | BM17: 0 | BN17: 0 | BO17: 0 | BP17: 0 | BQ17: 0 | BR17: 0 | BS17: 0 | BT17: 0 | BU17: 0 | BV17: 0 | BW17: 0 | BX17: 0 | BY17: 0 | BZ17: 0 | CA17: 0 | CB17: 0
A18: Phase B | B18: 47484 | C18: 48213 | D18: 730 | E18: 24 | F18: 10.6 | G18: 0 | H18: 0 | I18: 0 | J18: 0 | K18: 0 | L18: 0 | M18: 0 | N18: 0 | O18: 0 | P18: 0 | Q18: 3 | R18: 12 | S18: 9 | T18: 0 | U18: 0 | V18: 0 | W18: 0 | X18: 0 | Y18: 0 | Z18: 0 | AA18: 0 | AB18: 0 | AC18: 0 | AD18: 0 | AE18: 0 | AF18: 0 | AG18: 0 | AH18: 0 | AI18: 0 | AJ18: 0 | AK18: 0 | AL18: 0 | AM18: 0 | AN18: 0 | AO18: 0 | AP18: 0 | AQ18: 0 | AR18: 0 | AS18: 0 | AT18: 0 | AU18: 0 | AV18: 0 | AW18: 0 | AX18: 0 | AY18: 0 | AZ18: 0 | BA18: 0 | BB18: 0 | BC18: 0 | BD18: 0 | BE18: 0 | BF18: 0 | BG18: 0 | BH18: 0 | BI18: 0 | BJ18: 0 | BK18: 0 | BL18: 0 | BM18: 0 | BN18: 0 | BO18: 0 | BP18: 0 | BQ18: 0 | BR18: 0 | BS18: 0 | BT18: 0 | BU18: 0 | BV18: 0 | BW18: 0 | BX18: 0 | BY18: 0 | BZ18: 0 | CA18: 0 | CB18: 0
A19: Phase C | B19: 48214 | C19: 48944 | D19: 731 | E19: 24 | F19: 13.2 | G19: 0 | H19: 0 | I19: 0 | J19: 0 | K19: 0 | L19: 0 | M19: 0 | N19: 0 | O19: 0 | P19: 0 | Q19: 0 | R19: 0 | S19: 3 | T19: 12 | U19: 9 | V19: 0 | W19: 0 | X19: 0 | Y19: 0 | Z19: 0 | AA19: 0 | AB19: 0 | AC19: 0 | AD19: 0 | AE19: 0 | AF19: 0 | AG19: 0 | AH19: 0 | AI19: 0 | AJ19: 0 | AK19: 0 | AL19: 0 | AM19: 0 | AN19: 0 | AO19: 0 | AP19: 0 | AQ19: 0 | AR19: 0 | AS19: 0 | AT19: 0 | AU19: 0 | AV19: 0 | AW19: 0 | AX19: 0 | AY19: 0 | AZ19: 0 | BA19: 0 | BB19: 0 | BC19: 0 | BD19: 0 | BE19: 0 | BF19: 0 | BG19: 0 | BH19: 0 | BI19: 0 | BJ19: 0 | BK19: 0 | BL19: 0 | BM19: 0 | BN19: 0 | BO19: 0 | BP19: 0 | BQ19: 0 | BR19: 0 | BS19: 0 | BT19: 0 | BU19: 0 | BV19: 0 | BW19: 0 | BX19: 0 | BY19: 0 | BZ19: 0 | CA19: 0 | CB19: 0
A20: Phase D | B20: 48945 | C20: 51501 | D20: 2557 | E20: 84.1 | F20: 26.1 | G20: 0 | H20: 0 | I20: 0 | J20: 0 | K20: 0 | L20: 0 | M20: 0 | N20: 0 | O20: 0 | P20: 0 | Q20: 0 | R20: 0 | S20: 0 | T20: 0 | U20: 3 | V20: 12 | W20: 12 | X20: 12 | Y20: 12 | Z20: 12 | AA20: 12 | AB20: 9 | AC20: 0 | AD20: 0 | AE20: 0 | AF20: 0 | AG20: 0 | AH20: 0 | AI20: 0 | AJ20: 0 | AK20: 0 | AL20: 0 | AM20: 0 | AN20: 0 | AO20: 0 | AP20: 0 | AQ20: 0 | AR20: 0 | AS20: 0 | AT20: 0 | AU20: 0 | AV20: 0 | AW20: 0 | AX20: 0 | AY20: 0 | AZ20: 0 | BA20: 0 | BB20: 0 | BC20: 0 | BD20: 0 | BE20: 0 | BF20: 0 | BG20: 0 | BH20: 0 | BI20: 0 | BJ20: 0 | BK20: 0 | BL20: 0 | BM20: 0 | BN20: 0 | BO20: 0 | BP20: 0 | BQ20: 0 | BR20: 0 | BS20: 0 | BT20: 0 | BU20: 0 | BV20: 0 | BW20: 0 | BX20: 0 | BY20: 0 | BZ20: 0 | CA20: 0 | CB20: 0
A21: Phase E | B21: 51502 | C21: 56979 | D21: 5478 | E21: 180.1 | F21: 12.7 | G21: 0 | H21: 0 | I21: 0 | J21: 0 | K21: 0 | L21: 0 | M21: 0 | N21: 0 | O21: 0 | P21: 0 | Q21: 0 | R21: 0 | S21: 0 | T21: 0 | U21: 0 | V21: 0 | W21: 0 | X21: 0 | Y21: 0 | Z21: 0 | AA21: 0 | AB21: 3 | AC21: 12 | AD21: 12 | AE21: 12 | AF21: 12 | AG21: 12 | AH21: 12 | AI21: 12 | AJ21: 12 | AK21: 12 | AL21: 12 | AM21: 12 | AN21: 12 | AO21: 12 | AP21: 12 | AQ21: 9 | AR21: 0 | AS21: 0 | AT21: 0 | AU21: 0 | AV21: 0 | AW21: 0 | AX21: 0 | AY21: 0 | AZ21: 0 | BA21: 0 | BB21: 0 | BC21: 0 | BD21: 0 | BE21: 0 | BF21: 0 | BG21: 0 | BH21: 0 | BI21: 0 | BJ21: 0 | BK21: 0 | BL21: 0 | BM21: 0 | BN21: 0 | BO21: 0 | BP21: 0 | BQ21: 0 | BR21: 0 | BS21: 0 | BT21: 0 | BU21: 0 | BV21: 0 | BW21: 0 | BX21: 0 | BY21: 0 | BZ21: 0 | CA21: 0 | CB21: 0
A22: Phase X | B22: 56980 | C22: 58256 | D22: 1277 | E22: 42 | F22: 41.8 | G22: 0 | H22: 0 | I22: 0 | J22: 0 | K22: 0 | L22: 0 | M22: 0 | N22: 0 | O22: 0 | P22: 0 | Q22: 0 | R22: 0 | S22: 0 | T22: 0 | U22: 0 | V22: 0 | W22: 0 | X22: 0 | Y22: 0 | Z22: 0 | AA22: 0 | AB22: 0 | AC22: 0 | AD22: 0 | AE22: 0 | AF22: 0 | AG22: 0 | AH22: 0 | AI22: 0 | AJ22: 0 | AK22: 0 | AL22: 0 | AM22: 0 | AN22: 0 | AO22: 0 | AP22: 0 | AQ22: 3 | AR22: 12 | AS22: 12 | AT22: 12 | AU22: 3 | AV22: 0 | AW22: 0 | AX22: 0 | AY22: 0 | AZ22: 0 | BA22: 0 | BB22: 0 | BC22: 0 | BD22: 0 | BE22: 0 | BF22: 0 | BG22: 0 | BH22: 0 | BI22: 0 | BJ22: 0 | BK22: 0 | BL22: 0 | BM22: 0 | BN22: 0 | BO22: 0 | BP22: 0 | BQ22: 0 | BR22: 0 | BS22: 0 | BT22: 0 | BU22: 0 | BV22: 0 | BW22: 0 | BX22: 0 | BY22: 0 | BZ22: 0 | CA22: 0 | CB22: 0
B25: Schedule Scenario ID | C25: 2 | L25: Click to draw
B26: Scenario Name | C26: ORCA Optimistic Schedule
B27: Scenario Description | C27: Accelerated schedule used for sensitivity analysis, assuming efficient design maturation, procurement and integration.
B28: Rationale | C28: Phase durations are reduced ~15% relative to the nominal schedule while retaining the ORCA phase structure.
B29: Source Doc | C29: ORCA CADRe Part A — Project Phase Schedule; sensitivity scenario
B31: Phase | C31: Expected Start | D31: Expected End | E31: Total D | F31: Total M | G31: 2020 | H31: 2021 | I31: 2022 | J31: 2023 | K31: 2024 | L31: 2025 | M31: 2026 | N31: 2027 | O31: 2028 | P31: 2029 | Q31: 2030 | R31: 2031 | S31: 2032 | T31: 2033 | U31: 2034 | V31: 2035 | W31: 2036 | X31: 2037 | Y31: 2038 | Z31: 2039 | AA31: 2040 | AB31: 2041 | AC31: 2042 | AD31: 2043 | AE31: 2044 | AF31: 2045 | AG31: 2046 | AH31: 2047 | AI31: 2048 | AJ31: 2049 | AK31: 2050 | AL31: 2051 | AM31: 2052 | AN31: 2053 | AO31: 2054 | AP31: 2055 | AQ31: 2056 | AR31: 2057 | AS31: 2058 | AT31: 2059 | AU31: 2060 | AV31: 2061 | AW31: 2062 | AX31: 2063 | AY31: 2064 | AZ31: 2065 | BA31: 2066 | BB31: 2067 | BC31: 2068 | BD31: 2069 | BE31: 2070 | BF31: 2071 | BG31: 2072 | BH31: 2073 | BI31: 2074 | BJ31: 2075 | BK31: 2076 | BL31: 2077 | BM31: 2078 | BN31: 2079 | BO31: 2080 | BP31: 2081 | BQ31: 2082 | BR31: 2083 | BS31: 2084 | BT31: 2085 | BU31: 2086 | BV31: 2087 | BW31: 2088 | BX31: 2089 | BY31: 2090 | BZ31: 2091 | CA31: 2092 | CB31: 2093
A32: Phase 0 | B32: 46023 | C32: 46643 | D32: 621 | E32: 20.4 | F32: 8.9 | G32: 0 | H32: 0 | I32: 0 | J32: 0 | K32: 0 | L32: 0 | M32: 3 | N32: 12 | O32: 5.5 | P32: 0 | Q32: 0 | R32: 0 | S32: 0 | T32: 0 | U32: 0 | V32: 0 | W32: 0 | X32: 0 | Y32: 0 | Z32: 0 | AA32: 0 | AB32: 0 | AC32: 0 | AD32: 0 | AE32: 0 | AF32: 0 | AG32: 0 | AH32: 0 | AI32: 0 | AJ32: 0 | AK32: 0 | AL32: 0 | AM32: 0 | AN32: 0 | AO32: 0 | AP32: 0 | AQ32: 0 | AR32: 0 | AS32: 0 | AT32: 0 | AU32: 0 | AV32: 0 | AW32: 0 | AX32: 0 | AY32: 0 | AZ32: 0 | BA32: 0 | BB32: 0 | BC32: 0 | BD32: 0 | BE32: 0 | BF32: 0 | BG32: 0 | BH32: 0 | BI32: 0 | BJ32: 0 | BK32: 0 | BL32: 0 | BM32: 0 | BN32: 0 | BO32: 0 | BP32: 0 | BQ32: 0 | BR32: 0 | BS32: 0 | BT32: 0 | BU32: 0 | BV32: 0 | BW32: 0 | BX32: 0 | BY32: 0 | BZ32: 0 | CA32: 0 | CB32: 0
A33: Phase A | B33: 46644 | C33: 47264 | D33: 621 | E33: 20.4 | F33: 9.1 | G33: 0 | H33: 0 | I33: 0 | J33: 0 | K33: 0 | L33: 0 | M33: 0 | N33: 0 | O33: 6.6 | P33: 12 | Q33: 1.8 | R33: 0 | S33: 0 | T33: 0 | U33: 0 | V33: 0 | W33: 0 | X33: 0 | Y33: 0 | Z33: 0 | AA33: 0 | AB33: 0 | AC33: 0 | AD33: 0 | AE33: 0 | AF33: 0 | AG33: 0 | AH33: 0 | AI33: 0 | AJ33: 0 | AK33: 0 | AL33: 0 | AM33: 0 | AN33: 0 | AO33: 0 | AP33: 0 | AQ33: 0 | AR33: 0 | AS33: 0 | AT33: 0 | AU33: 0 | AV33: 0 | AW33: 0 | AX33: 0 | AY33: 0 | AZ33: 0 | BA33: 0 | BB33: 0 | BC33: 0 | BD33: 0 | BE33: 0 | BF33: 0 | BG33: 0 | BH33: 0 | BI33: 0 | BJ33: 0 | BK33: 0 | BL33: 0 | BM33: 0 | BN33: 0 | BO33: 0 | BP33: 0 | BQ33: 0 | BR33: 0 | BS33: 0 | BT33: 0 | BU33: 0 | BV33: 0 | BW33: 0 | BX33: 0 | BY33: 0 | BZ33: 0 | CA33: 0 | CB33: 0
A34: Phase B | B34: 47265 | C34: 47885 | D34: 621 | E34: 20.4 | F34: 9.5 | G34: 0 | H34: 0 | I34: 0 | J34: 0 | K34: 0 | L34: 0 | M34: 0 | N34: 0 | O34: 0 | P34: 0 | Q34: 10.2 | R34: 10.3 | S34: 0 | T34: 0 | U34: 0 | V34: 0 | W34: 0 | X34: 0 | Y34: 0 | Z34: 0 | AA34: 0 | AB34: 0 | AC34: 0 | AD34: 0 | AE34: 0 | AF34: 0 | AG34: 0 | AH34: 0 | AI34: 0 | AJ34: 0 | AK34: 0 | AL34: 0 | AM34: 0 | AN34: 0 | AO34: 0 | AP34: 0 | AQ34: 0 | AR34: 0 | AS34: 0 | AT34: 0 | AU34: 0 | AV34: 0 | AW34: 0 | AX34: 0 | AY34: 0 | AZ34: 0 | BA34: 0 | BB34: 0 | BC34: 0 | BD34: 0 | BE34: 0 | BF34: 0 | BG34: 0 | BH34: 0 | BI34: 0 | BJ34: 0 | BK34: 0 | BL34: 0 | BM34: 0 | BN34: 0 | BO34: 0 | BP34: 0 | BQ34: 0 | BR34: 0 | BS34: 0 | BT34: 0 | BU34: 0 | BV34: 0 | BW34: 0 | BX34: 0 | BY34: 0 | BZ34: 0 | CA34: 0 | CB34: 0
A35: Phase C | B35: 47886 | C35: 48506 | D35: 621 | E35: 20.4 | F35: 11.9 | G35: 0 | H35: 0 | I35: 0 | J35: 0 | K35: 0 | L35: 0 | M35: 0 | N35: 0 | O35: 0 | P35: 0 | Q35: 0 | R35: 1.7 | S35: 12 | T35: 6.6 | U35: 0 | V35: 0 | W35: 0 | X35: 0 | Y35: 0 | Z35: 0 | AA35: 0 | AB35: 0 | AC35: 0 | AD35: 0 | AE35: 0 | AF35: 0 | AG35: 0 | AH35: 0 | AI35: 0 | AJ35: 0 | AK35: 0 | AL35: 0 | AM35: 0 | AN35: 0 | AO35: 0 | AP35: 0 | AQ35: 0 | AR35: 0 | AS35: 0 | AT35: 0 | AU35: 0 | AV35: 0 | AW35: 0 | AX35: 0 | AY35: 0 | AZ35: 0 | BA35: 0 | BB35: 0 | BC35: 0 | BD35: 0 | BE35: 0 | BF35: 0 | BG35: 0 | BH35: 0 | BI35: 0 | BJ35: 0 | BK35: 0 | BL35: 0 | BM35: 0 | BN35: 0 | BO35: 0 | BP35: 0 | BQ35: 0 | BR35: 0 | BS35: 0 | BT35: 0 | BU35: 0 | BV35: 0 | BW35: 0 | BX35: 0 | BY35: 0 | BZ35: 0 | CA35: 0 | CB35: 0
A36: Phase D | B36: 48507 | C36: 50680 | D36: 2174 | E36: 71.5 | F36: 23.5 | G36: 0 | H36: 0 | I36: 0 | J36: 0 | K36: 0 | L36: 0 | M36: 0 | N36: 0 | O36: 0 | P36: 0 | Q36: 0 | R36: 0 | S36: 0 | T36: 5.4 | U36: 12 | V36: 12 | W36: 12 | X36: 12 | Y36: 12 | Z36: 6.1 | AA36: 0 | AB36: 0 | AC36: 0 | AD36: 0 | AE36: 0 | AF36: 0 | AG36: 0 | AH36: 0 | AI36: 0 | AJ36: 0 | AK36: 0 | AL36: 0 | AM36: 0 | AN36: 0 | AO36: 0 | AP36: 0 | AQ36: 0 | AR36: 0 | AS36: 0 | AT36: 0 | AU36: 0 | AV36: 0 | AW36: 0 | AX36: 0 | AY36: 0 | AZ36: 0 | BA36: 0 | BB36: 0 | BC36: 0 | BD36: 0 | BE36: 0 | BF36: 0 | BG36: 0 | BH36: 0 | BI36: 0 | BJ36: 0 | BK36: 0 | BL36: 0 | BM36: 0 | BN36: 0 | BO36: 0 | BP36: 0 | BQ36: 0 | BR36: 0 | BS36: 0 | BT36: 0 | BU36: 0 | BV36: 0 | BW36: 0 | BX36: 0 | BY36: 0 | BZ36: 0 | CA36: 0 | CB36: 0
A37: Phase E | B37: 50681 | C37: 55336 | D37: 4656 | E37: 153.1 | F37: 11.4 | G37: 0 | H37: 0 | I37: 0 | J37: 0 | K37: 0 | L37: 0 | M37: 0 | N37: 0 | O37: 0 | P37: 0 | Q37: 0 | R37: 0 | S37: 0 | T37: 0 | U37: 0 | V37: 0 | W37: 0 | X37: 0 | Y37: 0 | Z37: 5.9 | AA37: 12 | AB37: 12 | AC37: 12 | AD37: 12 | AE37: 12 | AF37: 12 | AG37: 12 | AH37: 12 | AI37: 12 | AJ37: 12 | AK37: 12 | AL37: 12 | AM37: 3.1 | AN37: 0 | AO37: 0 | AP37: 0 | AQ37: 0 | AR37: 0 | AS37: 0 | AT37: 0 | AU37: 0 | AV37: 0 | AW37: 0 | AX37: 0 | AY37: 0 | AZ37: 0 | BA37: 0 | BB37: 0 | BC37: 0 | BD37: 0 | BE37: 0 | BF37: 0 | BG37: 0 | BH37: 0 | BI37: 0 | BJ37: 0 | BK37: 0 | BL37: 0 | BM37: 0 | BN37: 0 | BO37: 0 | BP37: 0 | BQ37: 0 | BR37: 0 | BS37: 0 | BT37: 0 | BU37: 0 | BV37: 0 | BW37: 0 | BX37: 0 | BY37: 0 | BZ37: 0 | CA37: 0 | CB37: 0
A38: Phase X | B38: 55337 | C38: 56422 | D38: 1086 | E38: 35.7 | F38: 37.6 | G38: 0 | H38: 0 | I38: 0 | J38: 0 | K38: 0 | L38: 0 | M38: 0 | N38: 0 | O38: 0 | P38: 0 | Q38: 0 | R38: 0 | S38: 0 | T38: 0 | U38: 0 | V38: 0 | W38: 0 | X38: 0 | Y38: 0 | Z38: 0 | AA38: 0 | AB38: 0 | AC38: 0 | AD38: 0 | AE38: 0 | AF38: 0 | AG38: 0 | AH38: 0 | AI38: 0 | AJ38: 0 | AK38: 0 | AL38: 0 | AM38: 9 | AN38: 12 | AO38: 12 | AP38: 2.7 | AQ38: 0 | AR38: 0 | AS38: 0 | AT38: 0 | AU38: 0 | AV38: 0 | AW38: 0 | AX38: 0 | AY38: 0 | AZ38: 0 | BA38: 0 | BB38: 0 | BC38: 0 | BD38: 0 | BE38: 0 | BF38: 0 | BG38: 0 | BH38: 0 | BI38: 0 | BJ38: 0 | BK38: 0 | BL38: 0 | BM38: 0 | BN38: 0 | BO38: 0 | BP38: 0 | BQ38: 0 | BR38: 0 | BS38: 0 | BT38: 0 | BU38: 0 | BV38: 0 | BW38: 0 | BX38: 0 | BY38: 0 | BZ38: 0 | CA38: 0 | CB38: 0
B48: Schedule Scenario ID | C48: 3 | L48: Click to draw
B49: Scenario Name | C49: ORCA Pessimistic Schedule
B50: Scenario Description | C50: Delayed schedule used for sensitivity analysis, assuming additional design, test, procurement and integration delays.
B51: Rationale | C51: Phase durations are increased ~20% relative to the nominal schedule to represent schedule-risk sensitivity.
B52: Source Doc | C52: ORCA CADRe Part A — Project Phase Schedule; sensitivity scenario
B54: PM | C54: Expected Start | D54: Expected End | E54: Total D | F54: Total M | G54: 2020 | H54: 2021 | I54: 2022 | J54: 2023 | K54: 2024 | L54: 2025 | M54: 2026 | N54: 2027 | O54: 2028 | P54: 2029 | Q54: 2030 | R54: 2031 | S54: 2032 | T54: 2033 | U54: 2034 | V54: 2035 | W54: 2036 | X54: 2037 | Y54: 2038 | Z54: 2039 | AA54: 2040 | AB54: 2041 | AC54: 2042 | AD54: 2043 | AE54: 2044 | AF54: 2045 | AG54: 2046 | AH54: 2047 | AI54: 2048 | AJ54: 2049 | AK54: 2050 | AL54: 2051 | AM54: 2052 | AN54: 2053 | AO54: 2054 | AP54: 2055 | AQ54: 2056 | AR54: 2057 | AS54: 2058 | AT54: 2059 | AU54: 2060 | AV54: 2061 | AW54: 2062 | AX54: 2063 | AY54: 2064 | AZ54: 2065 | BA54: 2066 | BB54: 2067 | BC54: 2068 | BD54: 2069 | BE54: 2070 | BF54: 2071 | BG54: 2072 | BH54: 2073 | BI54: 2074 | BJ54: 2075 | BK54: 2076 | BL54: 2077 | BM54: 2078 | BN54: 2079 | BO54: 2080 | BP54: 2081 | BQ54: 2082 | BR54: 2083 | BS54: 2084 | BT54: 2085 | BU54: 2086 | BV54: 2087 | BW54: 2088 | BX54: 2089 | BY54: 2090 | BZ54: 2091 | CA54: 2092 | CB54: 2093
A55: Phase 0 | B55: 46023 | C55: 46898 | D55: 876 | E55: 28.8 | F55: 11.3 | G55: 0 | H55: 0 | I55: 0 | J55: 0 | K55: 0 | L55: 0 | M55: 3 | N55: 12 | O55: 12 | P55: 1.8 | Q55: 0 | R55: 0 | S55: 0 | T55: 0 | U55: 0 | V55: 0 | W55: 0 | X55: 0 | Y55: 0 | Z55: 0 | AA55: 0 | AB55: 0 | AC55: 0 | AD55: 0 | AE55: 0 | AF55: 0 | AG55: 0 | AH55: 0 | AI55: 0 | AJ55: 0 | AK55: 0 | AL55: 0 | AM55: 0 | AN55: 0 | AO55: 0 | AP55: 0 | AQ55: 0 | AR55: 0 | AS55: 0 | AT55: 0 | AU55: 0 | AV55: 0 | AW55: 0 | AX55: 0 | AY55: 0 | AZ55: 0 | BA55: 0 | BB55: 0 | BC55: 0 | BD55: 0 | BE55: 0 | BF55: 0 | BG55: 0 | BH55: 0 | BI55: 0 | BJ55: 0 | BK55: 0 | BL55: 0 | BM55: 0 | BN55: 0 | BO55: 0 | BP55: 0 | BQ55: 0 | BR55: 0 | BS55: 0 | BT55: 0 | BU55: 0 | BV55: 0 | BW55: 0 | BX55: 0 | BY55: 0 | BZ55: 0 | CA55: 0 | CB55: 0
A56: Phase A | B56: 46899 | C56: 47775 | D56: 877 | E56: 28.8 | F56: 11.7 | G56: 0 | H56: 0 | I56: 0 | J56: 0 | K56: 0 | L56: 0 | M56: 0 | N56: 0 | O56: 0 | P56: 10.2 | Q56: 12 | R56: 6.6 | S56: 0 | T56: 0 | U56: 0 | V56: 0 | W56: 0 | X56: 0 | Y56: 0 | Z56: 0 | AA56: 0 | AB56: 0 | AC56: 0 | AD56: 0 | AE56: 0 | AF56: 0 | AG56: 0 | AH56: 0 | AI56: 0 | AJ56: 0 | AK56: 0 | AL56: 0 | AM56: 0 | AN56: 0 | AO56: 0 | AP56: 0 | AQ56: 0 | AR56: 0 | AS56: 0 | AT56: 0 | AU56: 0 | AV56: 0 | AW56: 0 | AX56: 0 | AY56: 0 | AZ56: 0 | BA56: 0 | BB56: 0 | BC56: 0 | BD56: 0 | BE56: 0 | BF56: 0 | BG56: 0 | BH56: 0 | BI56: 0 | BJ56: 0 | BK56: 0 | BL56: 0 | BM56: 0 | BN56: 0 | BO56: 0 | BP56: 0 | BQ56: 0 | BR56: 0 | BS56: 0 | BT56: 0 | BU56: 0 | BV56: 0 | BW56: 0 | BX56: 0 | BY56: 0 | BZ56: 0 | CA56: 0 | CB56: 0
...

Sheet 8 -  Milestones 
A1: ` Table of Contents
A3: 8 - Milestone Register
A4: Why we we asking:
B5: to double check your schedule
B6: based in IGMF rev F
B9: ID | C9: Phase | D9: Milestone | E9: Description | F9: Specify Date | G9: Actual or Planned? | H9: Type | I9: Milestone Description | J9: Used in Analysis?
B10: M1 | C10: Prep 1 | D10: Primus | E10: First Gate 0 of first dollar spent | H10: Governance | J10: Used to calculate sunk costs
B11: M2 | D11: Contract Award | E11: First R&D contract, grant or contribution signed | H11: Contract | J11: Used to calculate sunk costs
B12: M3 | D12: Final Review | E12: Last R&D contract, grant or contribution before Mission Gate 0 is Completed | H12: Contract | J12: Used to calculate sunk costs
B13: M4 | C13: Prep 2 | D13: Secundus | E13: Gate 0 which will lead to an R&D contract during Phase 0/A. Could be same as Mission Gate 0 but not always | H13: Governance | J13: not used in costing, used only for graphics on Gantt Chart
B14: M5 | D14: Contract Award | E14: First R&D contract signed after Mission Gate 1 | H14: Contract | J14: Used for parametric analysis
B15: M6 | D15: Final Review | E15: Last R&D contract ends after Mission Gate 1 | H15: Contract | J15: Used for parametric analysis
B16: M7 | C16: Phase 0 | D16: Phase 0 Start | E16: RAM Effort to prepare Gate 0 or Gate 1 Begins | H16: RAM | J16: Used to compute CSA Salaries
B17: M8 | D17: Gate 0 | E17: Policy cover (possibly though a Strategic Retreat) | H17: Governance | J17: not used in costing, used only for graphics on Gantt Chart
B18: M9 | D18: KDP-0 / Gate 1 | E18: Key Decision Point in CSA Governance Framework | H18: Governance | J18: not used in costing, used only for graphics on Gantt Chart
B19: M10 | D19: R1 | E19: Identification of Investment Options | H19: Governance | J19: not used in costing, used only for graphics on Gantt Chart
B20: M11 | D20: Contract Award | E20: Phase 0 Contract Award | H20: Contract | J20: Used for parametric analysis
B21: M12 | D21: PL-MCR | E21: Mission Concept Review | H21: Major Milestone | I21: MCR is conducted early in the mission planning process to assess the feasibility and viability of the mission concept. | J21: Major Milestones used to compute durations in paramateric and analogy
B22: M13 | D22: PL-MRR | E22: Mission Requirements Review | H22: Major Milestone | I22: MRR is conducted to establish and validate the specific requirements that the mission must meet to achieve its objectives. | J22: Major Milestones used to compute durations in paramateric and analogy
B23: M14 | D23: MDR | E23: Mission Definition Review | H23: Interim Milestone | I23: MDR is conducted to refine the mission concept and requirements further and to establish a more detailed plan for mission implementation. | J23: Minor Milestones are sometimes used to infer Major Milestones when those have not been specified
B24: M15 | D24: FR | E24: Contractor Phase 0 Final Review | H24: Contract | J24: Used for parametric analysis
B25: M16 | D25: R2 | E25: Investment Option Recommendation | H25: Governance | J25: not used in costing, used only for graphics on Gantt Chart
B26: M17 | D26: Phase 0 End | E26: RAM Effort for Phase 0 Ends | H26: RAM | J26: Used to compute CSA Salaries
B27: M18 | C27: Phase A | D27: Phase A Start | E27: RAM Effort to prepare Gate 2 Begins | H27: RAM | J27: Used to compute CSA Salaries
B28: M19 | D28: KDP-A / Gate 2 | E28: Key Decision Point in CSA Governance Framework | H28: Governance | J28: not used in costing, used only for graphics on Gantt Chart
B29: M20 | D29: Contract Award | E29: Phase A Contract Award | H29: Contract | J29: Used for parametric analysis
B30: M21 | D30: PL-SRR | E30: 47469 | G30: Planned | H30: Major Milestone | I30: SRR is conducted to establish and validate the high-level requirements that the system must meet to achieve its mission objectives. | J30: Minor Milestones are sometimes used to infer Major Milestones when those have not been specified
B31: M24 | D31: M-SRR | E31: 47483 | G31: Planned | H31: External Dependency | J31: Major Milestones used to compute durations in paramateric and analogy
D32: M-SDR | E32: 47362 | G32: Planned | H32: External Dependency
B33: M27 | D33: Final Review | E33: Contractor Phase A Final Review | H33: Contract | J33: Used for parametric analysis
B34: M28 | D34: Phase A End | E34: RAM Effort for Phase A Ends | H34: RAM | J34: Used to compute CSA Salaries
B35: M29 | C35: Phase B | D35: Phase B Start | E35: RAM Effort to prepare Phase B Begins | H35: RAM | J35: Used to compute CSA Salaries
