Workbook
Name Costing_Phases: '2 - Phasing Nomenclature'!$F$13:$F$26
Name Costing_Phases_PM: '2 - Phasing Nomenclature'!$I$13:$I$25

Sheet Cover Page
B3: CSA-FIN-RD-0589
B4: Version Draft 1.0
B5: 46286
B8: Cost Analysis Data Requirement (CADRe)
D9: CADRe Part C - Essential Programmatic Inputs
D10: ORCA (Ocean Reconnaissance and Chemistry Analyzer)
C16: Prepared by ORCA Project Team
C17: Reviewed by [TBD] | D17: TBD

Sheet Table of Contents
A1: ORCA CADRe Part C - Table of Contents
A3: # | B3: Sheet
A4: 1 | B4: Cover Page
A5: 2 | B5: 1 - Change History
A6: 3 | B6: 4d - CBS in JS format
A7: 4 | B7: 2 - Phasing Nomenclature
A8: 5 | B8: 3 - Phase Durations
A9: 6 | B9: PM's sched Scenarios
A10: 7 | B10: GR&A
A11: 8 | B11: 4 - RAM LoE
A12: 9 | B12: 5 - Risk Register
A13: 10 | B13: Risk Breakdown Structure
A14: 11 | B14: Raw Labour Rates
A15: 12 | B15: Labour Rates lookup
... A17: 14 | B17: Inflation Rate

Sheet 1 - Change History
A1: ` Table of Contents
A3: 2. Version Control - Baseline Tracker
A4: Purpose: | B4: To track the baseline across time
B5: hold the major and minor releases of the baseline
B9: Change history and associated files that contain the relevant data | G9: Reserved
B10: File Number | C10: Date | D10: File Version | E10: Author | F10: Changes | G10: Parent Baseline Name | H10: Baseline ID
G11: ORCA @ PREP1 | H11: 1
G12: ORCA @ KDP-0 | H12: 2
E13: MB | F13: Rebaseline: cruise duration increased following updated Jupiter gravity-assist trajectory analysis. | G13: ORCA @ MDR#2 | H13: 3
G14: ORCA @ PREP2 | H14: 4
G15: ORCA @ KDP-A | H15: 5
B16: CSA-FIN-RD-0587 | C16: 48933 | D16: Draft 1 | E16: MB | F16: Initial document ahead of Phase B | G16: ORCA @ KDP-B | H16: 6
G17: ORCA @ PDR | H17: 7
G18: ORCA @ CDR | H18: 8
B19: CSA-FIN-RD-0590 | C19: 46286 | D19: Draft 1 | E19: MB | F19: Update ahead of Gate 4: PDR and CDR complete, System Integration Review baseline. | G19: ORCA @ SIR | H19: 9 | I19: <<--- We are here now
G20: ORCA @ Launch (as flown) | H20: 10
G21: ORCA @ CR | H21: 11
G22: ORCA @ KDP-X | H22: 12
G23: ORCA @ end of life | H23: 13

Sheet 4d - CBS in JS format
A1: ` Table of Contents
A3: 4d. CBS (as self referencing list) for use as a javascript array
A4: Why we we asking:
B5: this page is auto-generated and used for drawing it out
E6: Self referencing list for dtree
A8: UID | B8: Parent ID | C8: Level | D8: Node Name | E8: CBS Code | F8: Depth | G8: Icon | H8: Notes | J8: Javascript Code | N8: Depth
A9: 1 | B9: -1 | C9: 1 | D9: Space Missions | F9: Taxon 1 | G9: Box.png | J9: ="datatable["&A9-1&"] = new Array(""" & A9 &""",""" & B9 &""",""" & D9 & """,""" & C9&""","""&""&G9&""");" -> datatable[0] = new Array("1","-1","Space Missions","1","Box.png"); | N9: Taxon 1
A10: 2 | B10: =A9 -> 1 | C10: 2 | D10: EO SAR Missions | F10: Taxon 2 | G10: EO.png | J10: ="datatable["&A10-1&"] = new Array(""" & A10 &""",""" & B10 &""",""" & D10 & """,""" & C10&""","""&""&G10&""");" -> datatable[1] = new Array("2","1","EO SAR Missions","2","EO.png"); | N10: Taxon 2
A11: =A10+1 -> 3 | B11: =A10 -> 2 | C11: 3 | D11: Radarsat Portfolio | F11: Phylum | G11: Pouch.png | J11: ="datatable["&A11-1&"] = new Array(""" & A11 &""",""" & B11 &""",""" & D11 & """,""" & C11&""","""&""&G11&""");" -> datatable[2] = new Array("3","2","Radarsat Portfolio","3","Pouch.png"); | N11: Phylum
A12: =A11+1 -> 4 | B12: =A$6 -> 0 | C12: 4 | D12: Radarsat 1 | F12: Mission | G12: Satellite.png | J12: ="datatable["&A12-1&"] = new Array(""" & A12 &""",""" & B12 &""",""" & D12 & """,""" & C12&""","""&""&G12&""");" -> datatable[3] = new Array("4","0","Radarsat 1","4","Satellite.png"); | N12: Mission
A13: =A12+1 -> 5 | B13: =A$6 -> 0 | C13: 4 | D13: Radarsat 2 | F13: Mission | G13: Satellite.png | J13: ="datatable["&A13-1&"] = new Array(""" & A13 &""",""" & B13 &""",""" & D13 & """,""" & C13&""","""&""&G13&""");" -> datatable[4] = new Array("5","0","Radarsat 2","4","Satellite.png"); | N13: Design Reference Mission
A14: =A13+1 -> 6 | B14: =A$6 -> 0 | C14: 4 | D14: Radarsat Constellation Mission | F14: Mission | G14: Satellite.png | J14: ="datatable["&A14-1&"] = new Array(""" & A14 &""",""" & B14 &""",""" & D14 & """,""" & C14&""","""&""&G14&""");" -> datatable[5] = new Array("6","0","Radarsat Constellation Mission","4","Satellite.png"); | N14: Segment
A15: =A14+1 -> 7 | B15: =A$6 -> 0 | C15: 4 | D15: Radarsat+ Replenishment | E15: 1 | F15: Mission | G15: Satellite.png | J15: ="datatable["&A15-1&"] = new Array(""" & A15 &""",""" & B15 &""",""" & D15 & """,""" & C15&""","""&""&G15&""");" -> datatable[6] = new Array("7","0","Radarsat+ Replenishment","4","Satellite.png"); | N15: System of Systems
A16: =A15+1 -> 8 | B16: =A$6 -> 0 | C16: 4 | D16: Radarsat+ Next Generation | F16: Mission | G16: Satellite.png | J16: ="datatable["&A16-1&"] = new Array(""" & A16 &""",""" & B16 &""",""" & D16 & """,""" & C16&""","""&""&G16&""");" -> datatable[7] = new Array("8","0","Radarsat+ Next Generation","4","Satellite.png"); | N16: System
A17: =A16+1 -> 9 | B17: =A$10 -> 2 | C17: 5 | D17: Analysis Scenario 1: RCM Proxy | F17: Design Reference Mission | G17: Scenario.png | J17: ="datatable["&A17-1&"] = new Array(""" & A17 &""",""" & B17 &""",""" & D17 & """,""" & C17&""","""&""&G17&""");" -> datatable[8] = new Array("9","2","Analysis Scenario 1: RCM Proxy","5","Scenario.png"); | N17: Subsystem
A18: =A17+1 -> 10 | B18: =A$10 -> 2 | C18: 5 | D18: Analysis Scenario 2: RCM+ | F18: Design Reference Mission | G18: Scenario.png | J18: ="datatable["&A18-1&"] = new Array(""" & A18 &""",""" & B18 &""",""" & D18 & """,""" & C18&""","""&""&G18&""");" -> datatable[9] = new Array("10","2","Analysis Scenario 2: RCM+","5","Scenario.png"); | N18: Assembly
A19: =A18+1 -> 11 | B19: =A$10 -> 2 | C19: 5 | D19: Analysis Scenario 3: Airbus concept | F19: Design Reference Mission | G19: Scenario.png | J19: ="datatable["&A19-1&"] = new Array(""" & A19 &""",""" & B19 &""",""" & D19 & """,""" & C19&""","""&""&G19&""");" -> datatable[10] = new Array("11","2","Analysis Scenario 3: Airbus concept","5","Scenario.png"); | N19: Component
A20: =A19+1 -> 12 | B20: =A$10 -> 2 | C20: 5 | D20: Analysis Scenario 4: MDA Chorus Data Buy | F20: Design Reference Mission | G20: Scenario.png | J20: ="datatable["&A20-1&"] = new Array(""" & A20 &""",""" & B20 &""",""" & D20 & """,""" & C20&""","""&""&G20&""");" -> datatable[11] = new Array("12","2","Analysis Scenario 4: MDA Chorus Data Buy","5","Scenario.png");
A21: =A20+1 -> 13 | B21: =A$10 -> 2 | C21: 5 | D21: Analysis Scenario 5: MDA Chorus+ | F21: Design Reference Mission | G21: Scenario.png | J21: ="datatable["&A21-1&"] = new Array(""" & A21 &""",""" & B21 &""",""" & D21 & """,""" & C21&""","""&""&G21&""");" -> datatable[12] = new Array("13","2","Analysis Scenario 5: MDA Chorus+","5","Scenario.png");
A22: =A21+1 -> 14 | B22: =A$10 -> 2 | C22: 5 | D22: Analysis Scenario 6: Airbus Sentinel 2 | F22: Design Reference Mission | G22: Scenario.png | J22: ="datatable["&A22-1&"] = new Array(""" & A22 &""",""" & B22 &""",""" & D22 & """,""" & C22&""","""&""&G22&""");" -> datatable[13] = new Array("14","2","Analysis Scenario 6: Airbus Sentinel 2","5","Scenario.png");
A23: =A22+1 -> 15 | B23: =A$16 -> 8 | C23: 6 | D23: Government Overhead and Oversight | E23: 1.1 | F23: Segment | G23: Government.png | H23: This WBS includes all CSA Oversight, OGD salaries, and basic overhead for the care and maintenance of CSA staff | J23: ="datatable["&A23-1&"] = new Array(""" & A23 &""",""" & B23 &""",""" & D23 & """,""" & C23&""","""&""&G23&""");" -> datatable[14] = new Array("15","8","Government Overhead and Oversight","6","Government.png");
A24: =A23+1 -> 16 | B24: =A$16 -> 8 | C24: 6 | D24: Space Segment | E24: 1.2 | F24: Segment | G24: Satellite.png | H24: The Space Segment includes things we launch into space | J24: ="datatable["&A24-1&"] = new Array(""" & A24 &""",""" & B24 &""",""" & D24 & """,""" & C24&""","""&""&G24&""");" -> datatable[15] = new Array("16","8","Space Segment","6","Satellite.png");
A25: =A24+1 -> 17 | B25: =A$16 -> 8 | C25: 6 | D25: Launch Segment | E25: 1.3 | F25: Segment | G25: Rocket.png | H25: The launch segment includes the launch vehicle and seom support services | J25: ="datatable["&A25-1&"] = new Array(""" & A25 &""",""" & B25 &""",""" & D25 & """,""" & C25&""","""&""&G25&""");" -> datatable[16] = new Array("17","8","Launch Segment","6","Rocket.png");
A26: =A25+1 -> 18 | B26: =A$16 -> 8 | C26: 6 | D26: Ground Segment | E26: 1.4 | F26: Segment | G26: Facility.png | H26: The ground segment includes the planning desgin and development of the GS, but not the Ops | J26: ="datatable["&A26-1&"] = new Array(""" & A26 &""",""" & B26 &""",""" & D26 & """,""" & C26&""","""&""&G26&""");" -> datatable[17] = new Array("18","8","Ground Segment","6","Facility.png");
A27: =A26+1 -> 19 | B27: =A$16 -> 8 | C27: 6 | D27: Ops Segment | E27: 1.5 | F27: Segment | G27: Ops.png | H27: Ops includes SatOps, Mission Ops, Science Ops - typically contracts | J27: ="datatable["&A27-1&"] = new Array(""" & A27 &""",""" & B27 &""",""" & D27 & """,""" & C27&""","""&""&G27&""");" -> datatable[18] = new Array("19","8","Ops Segment","6","Ops.png");
A28: =A27+1 -> 20 | B28: =A$16 -> 8 | C28: 6 | D28: Science Segment | E28: 1.6 | F28: Segment | G28: Science.png | H28: Typically G&C | J28: ="datatable["&A28-1&"] = new Array(""" & A28 &""",""" & B28 &""",""" & D28 & """,""" & C28&""","""&""&G28&""");" -> datatable[19] = new Array("20","8","Science Segment","6","Science.png");
A29: =A28+1 -> 21 | B29: =A$18 -> 10 | C29: 7 | D29: Gov't Oversight (Salaries and EBP) | E29: 1.1.1 | F29: System of Systems | G29: Government.png | J29: ="datatable["&A29-1&"] = new Array(""" & A29 &""",""" & B29 &""",""" & D29 & """,""" & C29&""","""&""&G29&""");" -> datatable[20] = new Array("21","10","Gov't Oversight (Salaries and EBP)","7","Government.png");
A30: =A29+1 -> 22 | B30: =A$18 -> 10 | C30: 7 | D30: Government Overhead | E30: 1.1.2 | F30: System of Systems | G30: Government.png | J30: ="datatable["&A30-1&"] = new Array(""" & A30 &""",""" & B30 &""",""" & D30 & """,""" & C30&""","""&""&G30&""");" -> datatable[21] = new Array("22","10","Government Overhead","7","Government.png");
A31: =A30+1 -> 23 | B31: =A29 -> 21 | C31: 8 | D31: CSA Oversight | E31: 1.1.1.1 | F31: System | G31: Government.png | J31: ="datatable["&A31-1&"] = new Array(""" & A31 &""",""" & B31 &""",""" & D31 & """,""" & C31&""","""&""&G31&""");" -> datatable[22] = new Array("23","21","CSA Oversight","8","Government.png");
A32: =A31+1 -> 24 | B32: =A29 -> 21 | C32: 8 | D32: OGD Oversight | E32: 1.1.1.2 | F32: System | G32: Government.png | J32: ="datatable["&A32-1&"] = new Array(""" & A32 &""",""" & B32 &""",""" & D32 & """,""" & C32&""","""&""&G32&""");" -> datatable[23] = new Array("24","21","OGD Oversight","8","Government.png");
A33: =A32+1 -> 25 | B33: =A31 -> 23 | C33: 9 | D33: CSA Project Team | E33: 1.1.1.1.1 | F33: Subsystem | G33: Government.png | H33: This CBS contains all salaries associated with the RAM of the Project team | J33: ="datatable["&A33-1&"] = new Array(""" & A33 &""",""" & B33 &""",""" & D33 & """,""" & C33&""","""&""&G33&""");" -> datatable[24] = new Array("25","23","CSA Project Team","9","Government.png");
A34: =A33+1 -> 26 | B34: =A31 -> 23 | C34: 9 | D34: CSA Internal Services | E34: 1.1.1.1.2 | F34: Subsystem | G34: Government.png | H34: This CBS contains all salaries associated with CSA internal services (finance, HR, audit, eval, policy, Executives, IM, IT, contracts, shipping, etc) | J34: ="datatable["&A34-1&"] = new Array(""" & A34 &""",""" & B34 &""",""" & D34 & """,""" & C34&""","""&""&G34&""");" -> datatable[25] = new Array("26","23","CSA Internal Services","9","Government.png");
A35: =A34+1 -> 27 | B35: =A32 -> 24 | C35: 9 | D35: OGD Internal Services by MOU | E35: 1.1.1.2.1 | F35: Subsystem | G35: Government.png | J35: ="datatable["&A35-1&"] = new Array(""" & A35 &""",""" & B35 &""",""" & D35 & """,""" & C35&""","""&""&G35&""");" -> datatable[26] = new Array("27","24","OGD Internal Services by MOU","9","Government.png");
A36: =A35+1 -> 28 | B36: =A32 -> 24 | C36: 9 | D36: OGD User Departments by MOU (RAM portion) | E36: 1.1.1.2.2 | F36: Subsystem | G36: Government.png | J36: ="datatable["&A36-1&"] = new Array(""" & A36 &""",""" & B36 &""",""" & D36 & """,""" & C36&""","""&""&G36&""");" -> datatable[27] = new Array("28","24","OGD User Departments by MOU (RAM portion)","9","Government.png");
A37: =A36+1 -> 29 | B37: =A$29 -> 21 | C37: 10 | D37: Shared Services | E37: 1.1.1.2.1.1 | F37: Assembly | G37: Government.png | J37: ="datatable["&A37-1&"] = new Array(""" & A37 &""",""" & B37 &""",""" & D37 & """,""" & C37&""","""&""&G37&""");" -> datatable[28] = new Array("29","21","Shared Services","10","Government.png");
A38: =A37+1 -> 30 | B38: =A$29 -> 21 | C38: 10 | D38: SPAC | E38: 1.1.1.2.1.2 | F38: Assembly | G38: Government.png | J38: ="datatable["&A38-1&"] = new Array(""" & A38 &""",""" & B38 &""",""" & D38 & """,""" & C38&""","""&""&G38&""");" -> datatable[29] = new Array("30","21","SPAC","10","Government.png");
A39: =A38+1 -> 31 | B39: =A$29 -> 21 | C39: 10 | D39: Justice Canada | E39: 1.1.1.2.1.3 | F39: Assembly | G39: Government.png | J39: ="datatable["&A39-1&"] = new Array(""" & A39 &""",""" & B39 &""",""" & D39 & """,""" & C39&""","""&""&G39&""");" -> datatable[30] = new Array("31","21","Justice Canada","10","Government.png");
A40: =A39+1 -> 32 | B40: =A$31 -> 23 | C40: 10 | D40: ECCC | E40: 1.1.1.2.2.1 | F40: Assembly | G40: Government.png | J40: ="datatable["&A40-1&"] = new Array(""" & A40 &""",""" & B40 &""",""" & D40 & """,""" & C40&""","""&""&G40&""");" -> datatable[31] = new Array("32","23","ECCC","10","Government.png");
A41: =A40+1 -> 33 | B41: =A$31 -> 23 | C41: 10 | D41: NRCAN | E41: 1.1.1.2.2.2 | F41: Assembly | G41: Government.png | J41: ="datatable["&A41-1&"] = new Array(""" & A41 &""",""" & B41 &""",""" & D41 & """,""" & C41&""","""&""&G41&""");" -> datatable[32] = new Array("33","23","NRCAN","10","Government.png");
A42: =A41+1 -> 34 | B42: =A$31 -> 23 | C42: 10 | D42: DND | E42: 1.1.1.2.2.3 | F42: Assembly | G42: Government.png | J42: ="datatable["&A42-1&"] = new Array(""" & A42 &""",""" & B42 &""",""" & D42 & """,""" & C42&""","""&""&G42&""");" -> datatable[33] = new Array("34","23","DND","10","Government.png");
...

Sheet 2 - Phasing Nomenclature
A1: ` Table of Contents
A3: 7 - Phasing Nomenclature | I3: What do you call your phases?
A4: Why we we asking:
B5: 1. To normalize the naming convention across all investments.
B6: 2. Math Models are based on Costing Sub-Phase.
B7: 3. We want to output results in your naming convention and scope.
B10: Based on IGMF rev E | F10: Based on CSA-FIN-RPT-0072
A11: Phasing according to | E11: Phasing according to | I11: Phasing according to
A12: EPMO | E12: Costing | I12: PM
E13: PREP | F13: PREP 1 | G13: Prototyping Activities (before Gate 1)
A14: Pre-Project | B14: Option Analysis & Planning Phase | C14: Pre-Phase 0 | F14: PREP 2 | G14: Prototyping Activities (during Phase 0/A)
C15: Phase 0 | E15: Phase 0/A | F15: Phase 0 | G15: Concept & Feasibility | I15: Phase 0
A16: Project | B16: Definition Phase | C16: Detailed Project Requirements | F16: Phase A | G16: Mission Requirements | I16: Phase A
C17: Preliminary Definition | E17: Phase B/C | F17: Phase B | G17: Preliminary Design | I17: Phase B
C18: Detailed Definition | F18: Phase C | G18: Detailed Design | I18: Phase C
B19: Implementation Phase | C19: Implementation | E19: Phase D | F19: MAIT | G19: Manufacturing, Assembly, Integration and Test of Canadian Subsystems and Components | I19: Phase D
F20: SAIT | G20: Spacecraft Level Assembly, Test | I20: Phase D
F21: LEOP | G21: Lauch and early operations | I21: Phase D
A22: Post-Project | B22: Post-Implementation Phase | C22: Operations & Disposal | E22: Phase E | F22: Phase E | G22: Nominal Operations (per design life) | I22: Phase E
E23: Phase E (EXT) | F23: Phase X | G23: Extended operations (mission extension)
E24: Phase F | F24: Phase F | G24: Disposal (incl. post-mortem audit reports) | I24: Phase F
E25: Phase G | F25: Phase G | G25: Post-Mortem science utilization

Sheet 3 - Phase Durations
A1: ` Table of Contents
A3: 7b - Phasing Durations
A4: Why we we asking:
B5: 1. Durations affect Govt Salaries calculations
B6: 2. Durations affect Parametric estimates for Space segment, ground segment, ops
B7: 3. Schedule Scenarios are inputs to sensitivity analysis
B9: Schedule Scenario ID | C9: 1
B10: Scenario Name | C10: Nominal Schedule Used by Gaby for RAM calculation (PM Nomenclature)
B11: Scenario Description | C11: Phases 0 through F
B12: Rationale | C12: ORCA concept-stage schedule, consistent with CADRe Part A section 2.5
B13: Source Doc | C13: CADRe Part A
B15: Phase | C15: Expected Start | D15: Expected End | E15: Total D | F15: Total M | G15: 2026 | H15: =G15+1 -> 2027 | I15: =H15+1 -> 2028 | J15: =I15+1 -> 2029 | K15: =J15+1 -> 2030 | L15: =K15+1 -> 2031 | M15: =L15+1 -> 2032 | N15: =M15+1 -> 2033 | O15: =N15+1 -> 2034 | ... AO15: =AN15+1 -> 2060
B16: Phase 0 | C16: 46023 | D16: 46752 | E16: =D16-C16 -> 729 | F16: =E16/365*12 -> 23.967123 | G16: =MAX(MIN($D16,DATE(G$15,3,31))-MAX($C16,DATE(G$15-1,4,1))+1,0)/365*12 -> 2.9589041 | H16: =MAX(MIN($D16,DATE(H$15,3,31))-MAX($C16,DATE(H$15-1,4,1))+1,0)/365*12 -> 12 | I16: =MAX(MIN($D16,DATE(I$15,3,31))-MAX($C16,DATE(I$15-1,4,1))+1,0)/365*12 -> 9.0410959 | J16: =MAX(MIN($D16,DATE(J$15,3,31))-MAX($C16,DATE(J$15-1,4,1))+1,0)/365*12 -> 0 | K16: =MAX(MIN($D16,DATE(K$15,3,31))-MAX($C16,DATE(K$15-1,4,1))+1,0)/365*12 -> 0 | L16: =MAX(MIN($D16,DATE(L$15,3,31))-MAX($C16,DATE(L$15-1,4,1))+1,0)/365*12 -> 0 | M16: =MAX(MIN($D16,DATE(M$15,3,31))-MAX($C16,DATE(M$15-1,4,1))+1,0)/365*12 -> 0 | N16: =MAX(MIN($D16,DATE(N$15,3,31))-MAX($C16,DATE(N$15-1,4,1))+1,0)/365*12 -> 0 | ... AO16: =MAX(MIN($D16,DATE(AO$15,3,31))-MAX($C16,DATE(AO$15-1,4,1))+1,0)/365*12 -> 0
B17: Phase A | C17: =D16+1 -> 46753 | D17: 47483 | E17: =D17-C17 -> 730 | F17: =E17/365*12 -> 24 | G17: =MAX(MIN($D17,DATE(G$15,3,31))-MAX($C17,DATE(G$15-1,4,1))+1,0)/365*12 -> 0 | H17: =MAX(MIN($D17,DATE(H$15,3,31))-MAX($C17,DATE(H$15-1,4,1))+1,0)/365*12 -> 0 | I17: =MAX(MIN($D17,DATE(I$15,3,31))-MAX($C17,DATE(I$15-1,4,1))+1,0)/365*12 -> 2.9917808 | J17: =MAX(MIN($D17,DATE(J$15,3,31))-MAX($C17,DATE(J$15-1,4,1))+1,0)/365*12 -> 12 | K17: =MAX(MIN($D17,DATE(K$15,3,31))-MAX($C17,DATE(K$15-1,4,1))+1,0)/365*12 -> 9.0410959 | L17: =MAX(MIN($D17,DATE(L$15,3,31))-MAX($C17,DATE(L$15-1,4,1))+1,0)/365*12 -> 0 | M17: =MAX(MIN($D17,DATE(M$15,3,31))-MAX($C17,DATE(M$15-1,4,1))+1,0)/365*12 -> 0 | N17: =MAX(MIN($D17,DATE(N$15,3,31))-MAX($C17,DATE(N$15-1,4,1))+1,0)/365*12 -> 0 | ... AO17: =MAX(MIN($D17,DATE(AO$15,3,31))-MAX($C17,DATE(AO$15-1,4,1))+1,0)/365*12 -> 0
B18: Phase B1 | C18: =D17+1 -> 47484 | D18: 47848 | E18: =D18-C18 -> 364 | F18: =E18/365*12 -> 11.967123 | G18: =MAX(MIN($D18,DATE(G$15,3,31))-MAX($C18,DATE(G$15-1,4,1))+1,0)/365*12 -> 0 | H18: =MAX(MIN($D18,DATE(H$15,3,31))-MAX($C18,DATE(H$15-1,4,1))+1,0)/365*12 -> 0 | I18: =MAX(MIN($D18,DATE(I$15,3,31))-MAX($C18,DATE(I$15-1,4,1))+1,0)/365*12 -> 0 | J18: =MAX(MIN($D18,DATE(J$15,3,31))-MAX($C18,DATE(J$15-1,4,1))+1,0)/365*12 -> 0 | K18: =MAX(MIN($D18,DATE(K$15,3,31))-MAX($C18,DATE(K$15-1,4,1))+1,0)/365*12 -> 2.9589041 | L18: =MAX(MIN($D18,DATE(L$15,3,31))-MAX($C18,DATE(L$15-1,4,1))+1,0)/365*12 -> 9.0410959 | M18: =MAX(MIN($D18,DATE(M$15,3,31))-MAX($C18,DATE(M$15-1,4,1))+1,0)/365*12 -> 0 | N18: =MAX(MIN($D18,DATE(N$15,3,31))-MAX($C18,DATE(N$15-1,4,1))+1,0)/365*12 -> 0 | ... AO18: =MAX(MIN($D18,DATE(AO$15,3,31))-MAX($C18,DATE(AO$15-1,4,1))+1,0)/365*12 -> 0
B19: Phase B2 | C19: =D18+1 -> 47849 | D19: 48213 | E19: =D19-C19 -> 364 | F19: =E19/365*12 -> 11.967123 | G19: =MAX(MIN($D19,DATE(G$15,3,31))-MAX($C19,DATE(G$15-1,4,1))+1,0)/365*12 -> 0 | H19: =MAX(MIN($D19,DATE(H$15,3,31))-MAX($C19,DATE(H$15-1,4,1))+1,0)/365*12 -> 0 | I19: =MAX(MIN($D19,DATE(I$15,3,31))-MAX($C19,DATE(I$15-1,4,1))+1,0)/365*12 -> 0 | J19: =MAX(MIN($D19,DATE(J$15,3,31))-MAX($C19,DATE(J$15-1,4,1))+1,0)/365*12 -> 0 | K19: =MAX(MIN($D19,DATE(K$15,3,31))-MAX($C19,DATE(K$15-1,4,1))+1,0)/365*12 -> 0 | L19: =MAX(MIN($D19,DATE(L$15,3,31))-MAX($C19,DATE(L$15-1,4,1))+1,0)/365*12 -> 2.9589041 | M19: =MAX(MIN($D19,DATE(M$15,3,31))-MAX($C19,DATE(M$15-1,4,1))+1,0)/365*12 -> 9.0410959 | N19: =MAX(MIN($D19,DATE(N$15,3,31))-MAX($C19,DATE(N$15-1,4,1))+1,0)/365*12 -> 0 | ... AO19: =MAX(MIN($D19,DATE(AO$15,3,31))-MAX($C19,DATE(AO$15-1,4,1))+1,0)/365*12 -> 0
B20: Phase C | C20: =D19+1 -> 48214 | D20: 48944 | E20: =D20-C20 -> 730 | F20: =E20/365*12 -> 24 | G20: =MAX(MIN($D20,DATE(G$15,3,31))-MAX($C20,DATE(G$15-1,4,1))+1,0)/365*12 -> 0 | H20: =MAX(MIN($D20,DATE(H$15,3,31))-MAX($C20,DATE(H$15-1,4,1))+1,0)/365*12 -> 0 | I20: =MAX(MIN($D20,DATE(I$15,3,31))-MAX($C20,DATE(I$15-1,4,1))+1,0)/365*12 -> 0 | J20: =MAX(MIN($D20,DATE(J$15,3,31))-MAX($C20,DATE(J$15-1,4,1))+1,0)/365*12 -> 0 | K20: =MAX(MIN($D20,DATE(K$15,3,31))-MAX($C20,DATE(K$15-1,4,1))+1,0)/365*12 -> 0 | L20: =MAX(MIN($D20,DATE(L$15,3,31))-MAX($C20,DATE(L$15-1,4,1))+1,0)/365*12 -> 0 | M20: =MAX(MIN($D20,DATE(M$15,3,31))-MAX($C20,DATE(M$15-1,4,1))+1,0)/365*12 -> 2.9917808 | N20: =MAX(MIN($D20,DATE(N$15,3,31))-MAX($C20,DATE(N$15-1,4,1))+1,0)/365*12 -> 12 | ... AO20: =MAX(MIN($D20,DATE(AO$15,3,31))-MAX($C20,DATE(AO$15-1,4,1))+1,0)/365*12 -> 0
B21: Phase D | C21: =D20+1 -> 48945 | D21: 51501 | E21: =D21-C21 -> 2556 | F21: =E21/365*12 -> 84.032877 | G21: =MAX(MIN($D21,DATE(G$15,3,31))-MAX($C21,DATE(G$15-1,4,1))+1,0)/365*12 -> 0 | H21: =MAX(MIN($D21,DATE(H$15,3,31))-MAX($C21,DATE(H$15-1,4,1))+1,0)/365*12 -> 0 | I21: =MAX(MIN($D21,DATE(I$15,3,31))-MAX($C21,DATE(I$15-1,4,1))+1,0)/365*12 -> 0 | J21: =MAX(MIN($D21,DATE(J$15,3,31))-MAX($C21,DATE(J$15-1,4,1))+1,0)/365*12 -> 0 | K21: =MAX(MIN($D21,DATE(K$15,3,31))-MAX($C21,DATE(K$15-1,4,1))+1,0)/365*12 -> 0 | L21: =MAX(MIN($D21,DATE(L$15,3,31))-MAX($C21,DATE(L$15-1,4,1))+1,0)/365*12 -> 0 | M21: =MAX(MIN($D21,DATE(M$15,3,31))-MAX($C21,DATE(M$15-1,4,1))+1,0)/365*12 -> 0 | N21: =MAX(MIN($D21,DATE(N$15,3,31))-MAX($C21,DATE(N$15-1,4,1))+1,0)/365*12 -> 0 | ... AO21: =MAX(MIN($D21,DATE(AO$15,3,31))-MAX($C21,DATE(AO$15-1,4,1))+1,0)/365*12 -> 0
B22: Phase E | C22: =D21+1 -> 51502 | D22: 56979 | E22: =D22-C22 -> 5477 | F22: =E22/365*12 -> 180.06575 | G22: =MAX(MIN($D22,DATE(G$15,3,31))-MAX($C22,DATE(G$15-1,4,1))+1,0)/365*12 -> 0 | H22: =MAX(MIN($D22,DATE(H$15,3,31))-MAX($C22,DATE(H$15-1,4,1))+1,0)/365*12 -> 0 | I22: =MAX(MIN($D22,DATE(I$15,3,31))-MAX($C22,DATE(I$15-1,4,1))+1,0)/365*12 -> 0 | J22: =MAX(MIN($D22,DATE(J$15,3,31))-MAX($C22,DATE(J$15-1,4,1))+1,0)/365*12 -> 0 | K22: =MAX(MIN($D22,DATE(K$15,3,31))-MAX($C22,DATE(K$15-1,4,1))+1,0)/365*12 -> 0 | L22: =MAX(MIN($D22,DATE(L$15,3,31))-MAX($C22,DATE(L$15-1,4,1))+1,0)/365*12 -> 0 | M22: =MAX(MIN($D22,DATE(M$15,3,31))-MAX($C22,DATE(M$15-1,4,1))+1,0)/365*12 -> 0 | N22: =MAX(MIN($D22,DATE(N$15,3,31))-MAX($C22,DATE(N$15-1,4,1))+1,0)/365*12 -> 0 | ... AO22: =MAX(MIN($D22,DATE(AO$15,3,31))-MAX($C22,DATE(AO$15-1,4,1))+1,0)/365*12 -> 0
B23: Phase X | C23: =D22+1 -> 56980 | D23: 58256 | E23: =D23-C23 -> 1276 | F23: =E23/365*12 -> 41.950685 | G23: =MAX(MIN($D23,DATE(G$15,3,31))-MAX($C23,DATE(G$15-1,4,1))+1,0)/365*12 -> 0 | H23: =MAX(MIN($D23,DATE(H$15,3,31))-MAX($C23,DATE(H$15-1,4,1))+1,0)/365*12 -> 0 | I23: =MAX(MIN($D23,DATE(I$15,3,31))-MAX($C23,DATE(I$15-1,4,1))+1,0)/365*12 -> 0 | J23: =MAX(MIN($D23,DATE(J$15,3,31))-MAX($C23,DATE(J$15-1,4,1))+1,0)/365*12 -> 0 | K23: =MAX(MIN($D23,DATE(K$15,3,31))-MAX($C23,DATE(K$15-1,4,1))+1,0)/365*12 -> 0 | L23: =MAX(MIN($D23,DATE(L$15,3,31))-MAX($C23,DATE(L$15-1,4,1))+1,0)/365*12 -> 0 | M23: =MAX(MIN($D23,DATE(M$15,3,31))-MAX($C23,DATE(M$15-1,4,1))+1,0)/365*12 -> 0 | N23: =MAX(MIN($D23,DATE(N$15,3,31))-MAX($C23,DATE(N$15-1,4,1))+1,0)/365*12 -> 0 | ... AO23: =MAX(MIN($D23,DATE(AO$15,3,31))-MAX($C23,DATE(AO$15-1,4,1))+1,0)/365*12 -> 2.9917808
B24: Phase F | C24: =D23+1 -> 58257 | D24: =C24+180 -> 58437 | E24: =D24-C24 -> 180 | F24: =E24/365*12 -> 5.9178082 | G24: =MAX(MIN($D24,DATE(G$15,3,31))-MAX($C24,DATE(G$15-1,4,1))+1,0)/365*12 -> 0 | H24: =MAX(MIN($D24,DATE(H$15,3,31))-MAX($C24,DATE(H$15-1,4,1))+1,0)/365*12 -> 0 | I24: =MAX(MIN($D24,DATE(I$15,3,31))-MAX($C24,DATE(I$15-1,4,1))+1,0)/365*12 -> 0 | J24: =MAX(MIN($D24,DATE(J$15,3,31))-MAX($C24,DATE(J$15-1,4,1))+1,0)/365*12 -> 0 | K24: =MAX(MIN($D24,DATE(K$15,3,31))-MAX($C24,DATE(K$15-1,4,1))+1,0)/365*12 -> 0 | L24: =MAX(MIN($D24,DATE(L$15,3,31))-MAX($C24,DATE(L$15-1,4,1))+1,0)/365*12 -> 0 | M24: =MAX(MIN($D24,DATE(M$15,3,31))-MAX($C24,DATE(M$15-1,4,1))+1,0)/365*12 -> 0 | N24: =MAX(MIN($D24,DATE(N$15,3,31))-MAX($C24,DATE(N$15-1,4,1))+1,0)/365*12 -> 0 | ... AO24: =MAX(MIN($D24,DATE(AO$15,3,31))-MAX($C24,DATE(AO$15-1,4,1))+1,0)/365*12 -> 5.9506849
B26: Phase D1-MAIT | C26: =C21 -> 48945 | D26: =EDATE(C26,54)-1 -> 50586 | E26: =D26-C26 -> 1641 | F26: =E26/365*12 -> 53.950685 | G26: =MAX(MIN($D26,DATE(G$15,3,31))-MAX($C26,DATE(G$15-1,4,1))+1,0)/365*12 -> 0 | H26: =MAX(MIN($D26,DATE(H$15,3,31))-MAX($C26,DATE(H$15-1,4,1))+1,0)/365*12 -> 0 | I26: =MAX(MIN($D26,DATE(I$15,3,31))-MAX($C26,DATE(I$15-1,4,1))+1,0)/365*12 -> 0 | J26: =MAX(MIN($D26,DATE(J$15,3,31))-MAX($C26,DATE(J$15-1,4,1))+1,0)/365*12 -> 0 | K26: =MAX(MIN($D26,DATE(K$15,3,31))-MAX($C26,DATE(K$15-1,4,1))+1,0)/365*12 -> 0 | L26: =MAX(MIN($D26,DATE(L$15,3,31))-MAX($C26,DATE(L$15-1,4,1))+1,0)/365*12 -> 0 | M26: =MAX(MIN($D26,DATE(M$15,3,31))-MAX($C26,DATE(M$15-1,4,1))+1,0)/365*12 -> 0 | N26: =MAX(MIN($D26,DATE(N$15,3,31))-MAX($C26,DATE(N$15-1,4,1))+1,0)/365*12 -> 0 | ... AO26: =MAX(MIN($D26,DATE(AO$15,3,31))-MAX($C26,DATE(AO$15-1,4,1))+1,0)/365*12 -> 0
B27: Phase D2-SAIT | C27: =D26+1 -> 50587 | D27: =EDATE(C27,27)-1 -> 51409 | E27: =D27-C27 -> 822 | F27: =E27/365*12 -> 27.024658 | G27: =MAX(MIN($D27,DATE(G$15,3,31))-MAX($C27,DATE(G$15-1,4,1))+1,0)/365*12 -> 0 | H27: =MAX(MIN($D27,DATE(H$15,3,31))-MAX($C27,DATE(H$15-1,4,1))+1,0)/365*12 -> 0 | I27: =MAX(MIN($D27,DATE(I$15,3,31))-MAX($C27,DATE(I$15-1,4,1))+1,0)/365*12 -> 0 | J27: =MAX(MIN($D27,DATE(J$15,3,31))-MAX($C27,DATE(J$15-1,4,1))+1,0)/365*12 -> 0 | K27: =MAX(MIN($D27,DATE(K$15,3,31))-MAX($C27,DATE(K$15-1,4,1))+1,0)/365*12 -> 0 | L27: =MAX(MIN($D27,DATE(L$15,3,31))-MAX($C27,DATE(L$15-1,4,1))+1,0)/365*12 -> 0 | M27: =MAX(MIN($D27,DATE(M$15,3,31))-MAX($C27,DATE(M$15-1,4,1))+1,0)/365*12 -> 0 | N27: =MAX(MIN($D27,DATE(N$15,3,31))-MAX($C27,DATE(N$15-1,4,1))+1,0)/365*12 -> 0 | ... AO27: =MAX(MIN($D27,DATE(AO$15,3,31))-MAX($C27,DATE(AO$15-1,4,1))+1,0)/365*12 -> 0
B28: Phase D3-LEOP | C28: =D27+1 -> 51410 | D28: =D21 -> 51501 | E28: =D28-C28 -> 91 | F28: =E28/365*12 -> 2.9917808 | G28: =MAX(MIN($D28,DATE(G$15,3,31))-MAX($C28,DATE(G$15-1,4,1))+1,0)/365*12 -> 0 | H28: =MAX(MIN($D28,DATE(H$15,3,31))-MAX($C28,DATE(H$15-1,4,1))+1,0)/365*12 -> 0 | I28: =MAX(MIN($D28,DATE(I$15,3,31))-MAX($C28,DATE(I$15-1,4,1))+1,0)/365*12 -> 0 | J28: =MAX(MIN($D28,DATE(J$15,3,31))-MAX($C28,DATE(J$15-1,4,1))+1,0)/365*12 -> 0 | K28: =MAX(MIN($D28,DATE(K$15,3,31))-MAX($C28,DATE(K$15-1,4,1))+1,0)/365*12 -> 0 | L28: =MAX(MIN($D28,DATE(L$15,3,31))-MAX($C28,DATE(L$15-1,4,1))+1,0)/365*12 -> 0 | M28: =MAX(MIN($D28,DATE(M$15,3,31))-MAX($C28,DATE(M$15-1,4,1))+1,0)/365*12 -> 0 | N28: =MAX(MIN($D28,DATE(N$15,3,31))-MAX($C28,DATE(N$15-1,4,1))+1,0)/365*12 -> 0 | ... AO28: =MAX(MIN($D28,DATE(AO$15,3,31))-MAX($C28,DATE(AO$15-1,4,1))+1,0)/365*12 -> 0

Sheet PM's sched Scenarios
C1: ORCA Ref. | D1: ='3 - Phase Durations'!C16 -> 46023
A3: Phase | B3: Milestone | C3: ORCA Baseline | D3: Orbiter Platform (Partner Agency) | E3: ORCA Instrument Suite | F3: Worst case duration | G3: Worst case (+2 mo/phase) | H3: Realistic case duration | I3: Baseline: Realistic case date (1 month delay per phase) | J3: Optimistic case duration | K3: Optimistic case | L3: Comments
A4: Phase 0 | B4: Mission Concept Review (MCR) | C4: ='3 - Phase Durations'!D16 -> 46752 | D4: N/A | E4: N/A | F4: =(G4-'3 - Phase Durations'!C16)/30.44 -> 25.919842 | G4: =EDATE(C4,2) -> 46812 | H4: =(I4-'3 - Phase Durations'!C16)/30.44 -> 24.967148 | I4: =EDATE(C4,1) -> 46783 | J4: =(K4-'3 - Phase Durations'!C16)/30.44 -> 22.930355 | K4: =EDATE(C4,-1) -> 46721 | L4: End of Phase 0; mission concept baseline.
A5: Phase A | B5: System Requirements Review (SRR) | C5: ='3 - Phase Durations'!D17 -> 47483 | D5: N/A | E5: N/A | F5: =(G5-'3 - Phase Durations'!C16)/30.44 -> 51.905388 | G5: =EDATE(C5,4) -> 47603 | H5: =(I5-'3 - Phase Durations'!C16)/30.44 -> 49.901445 | I5: =EDATE(C5,2) -> 47542 | J5: =(K5-'3 - Phase Durations'!C16)/30.44 -> 45.959264 | K5: =EDATE(C5,-2) -> 47422 | L5: End of Phase A.
A6: Phase A | B6: ORCA Concept Rebaseline | C6: ='3 - Phase Durations'!C17+0.75*('3 - Phase Durations'!D17-'3 - Phase Durations'!C17) -> 47300.5 | D6: N/A | E6: N/A | F6: =(G6-'3 - Phase Durations'!C16)/30.44 -> 45.992116 | G6: =EDATE(C6,4) -> 47423 | H6: =(I6-'3 - Phase Durations'!C16)/30.44 -> 43.988173 | I6: =EDATE(C6,2) -> 47362 | J6: =(K6-'3 - Phase Durations'!C16)/30.44 -> 39.947438 | K6: =EDATE(C6,-2) -> 47239 | L6: Programmatic baseline update within Phase A. | N6: Phases | O6: Duration (months) | P6: Expected start | Q6: Expected finish
A7: Phase B | B7: Orbiter Bus / ORCA Instrument Suite Interface Complete | C7: ='3 - Phase Durations'!C18+0.6*('3 - Phase Durations'!D19-'3 - Phase Durations'!C18) -> 47921.4 | D7: Interface requirements | E7: Interface requirements | F7: =(G7-'3 - Phase Durations'!C16)/30.44 -> 68.396846 | G7: =EDATE(C7,6) -> 48105 | H7: =(I7-'3 - Phase Durations'!C16)/30.44 -> 65.374507 | I7: =EDATE(C7,3) -> 48013 | J7: =(K7-'3 - Phase Durations'!C16)/30.44 -> 59.395532 | K7: =EDATE(C7,-3) -> 47831 | L7: Partner-agency orbiter interface control document (ICD) finalized. | N7: ='3 - Phase Durations'!B16 -> Phase 0 | O7: ='3 - Phase Durations'!F16 -> 23.967123 | P7: ='3 - Phase Durations'!C16 -> 46023 | Q7: ='3 - Phase Durations'!D16 -> 46752
A8: Phase B | B8: Preliminary Design Review (PDR) | C8: ='3 - Phase Durations'!D19 -> 48213 | D8: Bus accommodation | E8: Preliminary design | F8: =(G8-'3 - Phase Durations'!C16)/30.44 -> 77.923784 | G8: =EDATE(C8,6) -> 48395 | H8: =(I8-'3 - Phase Durations'!C16)/30.44 -> 74.934297 | I8: =EDATE(C8,3) -> 48304 | J8: =(K8-'3 - Phase Durations'!C16)/30.44 -> 68.92247 | K8: =EDATE(C8,-3) -> 48121 | L8: End of Phase B (B1+B2). | N8: ='3 - Phase Durations'!B17 -> Phase A | O8: ='3 - Phase Durations'!F17 -> 24 | P8: ='3 - Phase Durations'!C17 -> 46753 | Q8: ='3 - Phase Durations'!D17 -> 47483
A9: Phase C | B9: Instrument Suite Environmental Qualification Complete | C9: ='3 - Phase Durations'!C20+0.6*('3 - Phase Durations'!D20-'3 - Phase Durations'!C20) -> 48652 | D9: N/A | E9: Qualification | F9: =(G9-'3 - Phase Durations'!C16)/30.44 -> 94.415243 | G9: =EDATE(C9,8) -> 48897 | H9: =(I9-'3 - Phase Durations'!C16)/30.44 -> 90.374507 | I9: =EDATE(C9,4) -> 48774 | J9: =(K9-'3 - Phase Durations'!C16)/30.44 -> 82.424442 | K9: =EDATE(C9,-4) -> 48532 | L9: Vibration / thermal-vacuum qualification of the ORCA instrument suite. | N9: ='3 - Phase Durations'!B18 -> Phase B1 | O9: ='3 - Phase Durations'!F18 -> 11.967123 | P9: ='3 - Phase Durations'!C18 -> 47484 | Q9: ='3 - Phase Durations'!D18 -> 47848
A10: Phase C | B10: Critical Design Review (CDR) | C10: ='3 - Phase Durations'!D20 -> 48944 | D10: Bus accommodation | E10: Critical design | F10: =(G10-'3 - Phase Durations'!C16)/30.44 -> 103.94218 | G10: =EDATE(C10,8) -> 49187 | H10: =(I10-'3 - Phase Durations'!C16)/30.44 -> 99.901445 | I10: =EDATE(C10,4) -> 49064 | J10: =(K10-'3 - Phase Durations'!C16)/30.44 -> 91.95138 | K10: =EDATE(C10,-4) -> 48822 | L10: End of Phase C. | N10: ='3 - Phase Durations'!B19 -> Phase B2 | O10: ='3 - Phase Durations'!F19 -> 11.967123 | P10: ='3 - Phase Durations'!C19 -> 47849 | Q10: ='3 - Phase Durations'!D19 -> 48213
A11: MAIT | B11: Manufacturing Readiness Review (MRR) | C11: ='3 - Phase Durations'!C26+0.5*('3 - Phase Durations'!D26-'3 - Phase Durations'!C26) -> 49765.5 | D11: N/A | E11: N/A | F11: =(G11-'3 - Phase Durations'!C16)/30.44 -> 132.98292 | G11: =EDATE(C11,10) -> 50071 | H11: =(I11-'3 - Phase Durations'!C16)/30.44 -> 127.95664 | I11: =EDATE(C11,5) -> 49918 | J11: =(K11-'3 - Phase Durations'!C16)/30.44 -> 117.93693 | K11: =EDATE(C11,-5) -> 49613 | L11: Mid-MAIT manufacturing readiness checkpoint. | N11: ='3 - Phase Durations'!B20 -> Phase C | O11: ='3 - Phase Durations'!F20 -> 24 | P11: ='3 - Phase Durations'!C20 -> 48214 | Q11: ='3 - Phase Durations'!D20 -> 48944
A12: MAIT | B12: Pre-Ship Review of Systems to Prime (PSR) | C12: ='3 - Phase Durations'!D21-180 -> 51321 | D12: Integration readiness | E12: Integration readiness | F12: =(G12-'3 - Phase Durations'!C16)/30.44 -> 184.03417 | G12: =EDATE(C12,10) -> 51625 | H12: =(I12-'3 - Phase Durations'!C16)/30.44 -> 179.07359 | I12: =EDATE(C12,5) -> 51474 | J12: =(K12-'3 - Phase Durations'!C16)/30.44 -> 169.08673 | K12: =EDATE(C12,-5) -> 51170 | L12: ~6 months before launch. | N12: ='3 - Phase Durations'!B21 -> Phase D | O12: ='3 - Phase Durations'!F21 -> 84.032877 | P12: ='3 - Phase Durations'!C21 -> 48945 | Q12: ='3 - Phase Durations'!D21 -> 51501
A13: SAIT | B13: Integrated Instrument Suite Functional Test Complete | C13: ='3 - Phase Durations'!D27-30 -> 51379 | D13: N/A | E13: Functional test | F13: =(G13-'3 - Phase Durations'!C16)/30.44 -> 185.9067 | G13: =EDATE(C13,10) -> 51682 | H13: =(I13-'3 - Phase Durations'!C16)/30.44 -> 180.97898 | I13: =EDATE(C13,5) -> 51532 | J13: =(K13-'3 - Phase Durations'!C16)/30.44 -> 170.92641 | K13: =EDATE(C13,-5) -> 51226 | L13: Ahead of System Integration Review. | N13: ='3 - Phase Durations'!B22 -> Phase E | O13: ='3 - Phase Durations'!F22 -> 180.06575 | P13: ='3 - Phase Durations'!C22 -> 51502 | Q13: ='3 - Phase Durations'!D22 -> 56979
A14: SAIT | B14: System Integration Review (SIR) | C14: ='3 - Phase Durations'!D27 -> 51409 | D14: Bus integration | E14: Instrument integration | F14: =(G14-'3 - Phase Durations'!C16)/30.44 -> 186.89225 | G14: =EDATE(C14,10) -> 51712 | H14: =(I14-'3 - Phase Durations'!C16)/30.44 -> 181.89882 | I14: =EDATE(C14,5) -> 51560 | J14: =(K14-'3 - Phase Durations'!C16)/30.44 -> 171.91196 | K14: =EDATE(C14,-5) -> 51256 | L14: ORCA integrated onto partner-agency orbiter bus. | N14: ='3 - Phase Durations'!B23 -> Phase X | O14: ='3 - Phase Durations'!F23 -> 41.950685 | P14: ='3 - Phase Durations'!C23 -> 56980 | Q14: ='3 - Phase Durations'!D23 -> 58256
A15: SAIT | B15: Acceptance Review (AR) | C15: ='3 - Phase Durations'!D21-90 -> 51411 | D15: Flight acceptance | E15: Flight acceptance | F15: =(G15-'3 - Phase Durations'!C16)/30.44 -> 186.9908 | G15: =EDATE(C15,10) -> 51715 | H15: =(I15-'3 - Phase Durations'!C16)/30.44 -> 181.96452 | I15: =EDATE(C15,5) -> 51562 | J15: =(K15-'3 - Phase Durations'!C16)/30.44 -> 171.97766 | K15: =EDATE(C15,-5) -> 51258 | L15: ~3 months before launch. | N15: ='3 - Phase Durations'!B24 -> Phase F | O15: ='3 - Phase Durations'!F24 -> 5.9178082 | P15: ='3 - Phase Durations'!C24 -> 58257 | Q15: ='3 - Phase Durations'!D24 -> 58437
A16: SAIT | B16: Flight Software and Autonomy Verification Complete | C16: ='3 - Phase Durations'!D21-60 -> 51441 | D16: N/A | E16: N/A | F16: =(G16-'3 - Phase Durations'!C16)/30.44 -> 187.97635 | G16: =EDATE(C16,10) -> 51745 | H16: =(I16-'3 - Phase Durations'!C16)/30.44 -> 182.95007 | I16: =EDATE(C16,5) -> 51592 | J16: =(K16-'3 - Phase Durations'!C16)/30.44 -> 172.96321 | K16: =EDATE(C16,-5) -> 51288 | L16: Autonomy and fault-management software verified. | N16: Total | O16: =SUM(O7:O15) -> 407.86849
A17: LEOP | B17: Pre-Ship Review – Spacecraft to Launch Site | C17: ='3 - Phase Durations'!D21-45 -> 51456 | D17: Bus checkout | E17: N/A | F17: =(G17-'3 - Phase Durations'!C16)/30.44 -> 188.46912 | G17: =EDATE(C17,10) -> 51760 | H17: =(I17-'3 - Phase Durations'!C16)/30.44 -> 183.44284 | I17: =EDATE(C17,5) -> 51607 | J17: =(K17-'3 - Phase Durations'!C16)/30.44 -> 173.45598 | K17: =EDATE(C17,-5) -> 51303 | L17: Before shipment to launch site.
A18: LEOP | B18: Launch | C18: ='3 - Phase Durations'!D21 -> 51501 | D18: N/A | E18: N/A | F18: =(G18-'3 - Phase Durations'!C16)/30.44 -> 189.94744 | G18: =EDATE(C18,10) -> 51805 | H18: =(I18-'3 - Phase Durations'!C16)/30.44 -> 184.92116 | I18: =EDATE(C18,5) -> 51652 | J18: =(K18-'3 - Phase Durations'!C16)/30.44 -> 174.9343 | K18: =EDATE(C18,-5) -> 51348 | L18: End of Phase D; Jupiter gravity-assist trajectory.
A19: LEOP | B19: Commissioning Review (CR) | C19: =C18+14 -> 51515 | D19: Bus checkout | E19: Instrument checkout | F19: =(G19-'3 - Phase Durations'!C16)/30.44 -> 190.40736 | G19: =EDATE(C19,10) -> 51819 | H19: =(I19-'3 - Phase Durations'!C16)/30.44 -> 185.38108 | I19: =EDATE(C19,5) -> 51666 | J19: =(K19-'3 - Phase Durations'!C16)/30.44 -> 175.39422 | K19: =EDATE(C19,-5) -> 51362 | L19: Post-launch systems checkout, ~2 weeks after launch.
A20: Phase E | B20: Start of Nominal Operations | C20: ='3 - Phase Durations'!C22 -> 51502 | D20: N/A | E20: Plume sampling begins | F20: =(G20-'3 - Phase Durations'!C16)/30.44 -> 191.98423 | G20: =EDATE(C20,12) -> 51867 | H20: =(I20-'3 - Phase Durations'!C16)/30.44 -> 185.93955 | I20: =EDATE(C20,6) -> 51683 | J20: =(K20-'3 - Phase Durations'!C16)/30.44 -> 173.94875 | K20: =EDATE(C20,-6) -> 51318 | L20: Start of Phase E.
A21: Phase E | B21: End of Nominal Operations | C21: ='3 - Phase Durations'!D22 -> 56979 | D21: N/A | E21: N/A | F21: =(G21-'3 - Phase Durations'!C16)/30.44 -> 371.94481 | G21: =EDATE(C21,12) -> 57345 | H21: =(I21-'3 - Phase Durations'!C16)/30.44 -> 365.90013 | I21: =EDATE(C21,6) -> 57161 | J21: =(K21-'3 - Phase Durations'!C16)/30.44 -> 353.87648 | K21: =EDATE(C21,-6) -> 56795 | L21: End of Phase E; 4-year prime science mission.
A22: Phase X | B22: End of Life / Disposal Operations Complete | C22: ='3 - Phase Durations'!D23 -> 58256 | D22: N/A | E22: N/A | F22: =(G22-'3 - Phase Durations'!C16)/30.44 -> 415.90013 | G22: =EDATE(C22,14) -> 58683 | H22: =(I22-'3 - Phase Durations'!C16)/30.44 -> 408.90276 | I22: =EDATE(C22,7) -> 58470 | J22: =(K22-'3 - Phase Durations'!C16)/30.44 -> 394.90802 | K22: =EDATE(C22,-7) -> 58044 | L22: End of Phase X; optional mission extension.
B29: ORCA Milestone Reference
B30: Milestone | C30: Realistic Date | E30: Phase | F30: Purpose
B31: Mission Concept Review (MCR) | C31: =C4 -> 46752 | E31: Phase 0 | F31: Mission concept baseline
B32: System Requirements Review (SRR) | C32: =C5 -> 47483 | E32: Phase A | F32: Requirements baseline
B33: ORCA Concept Rebaseline | C33: =C6 -> 47300.5 | E33: Phase A | F33: Programmatic baseline update
B34: Orbiter Bus / ORCA Instrument Suite Interface Complete | C34: =C7 -> 47921.4 | E34: Phase B | F34: Interface control document finalized
B35: Preliminary Design Review (PDR) | C35: =C8 -> 48213 | E35: Phase B | F35: Preliminary design maturity
B36: Instrument Suite Environmental Qualification Complete | C36: =C9 -> 48652 | E36: Phase C | F36: Instrument suite qualification
B37: Critical Design Review (CDR) | C37: =C10 -> 48944 | E37: Phase C | F37: Design baseline approval
B38: Manufacturing Readiness Review (MRR) | C38: =C11 -> 49765.5 | E38: MAIT | F38: Manufacturing readiness
B39: Pre-Ship Review of Systems to Prime (PSR) | C39: =C12 -> 51321 | E39: MAIT | F39: Transfer readiness
B40: Integrated Instrument Suite Functional Test Complete | C40: =C13 -> 51379 | E40: SAIT | F40: Functional test readiness
B41: System Integration Review (SIR) | C41: =C14 -> 51409 | E41: SAIT | F41: Integrated system readiness
B42: Acceptance Review (AR) | C42: =C15 -> 51411 | E42: SAIT | F42: Flight acceptance
... B49: End of Life / Disposal Operations Complete | C49: =C22 -> 58256 | E49: Phase X | F49: Mission closeout

Sheet GR&A
A2: Costing CSA Ground Rules & Assumptions template
A3: Last review | D3: 45747
A5: ID | B5: Catégorie | C5: Category | D5: Category | E5: Sub-category | F5: Items | G5: GR or A | H5: Title | I5: Description | J5: Phase | K5: CBS # linked to GR&A | L5: Impact on Project | M5: Impact on costing, methodology, models, tools & analysis | N5: Excepted source | O5: Do not delete | P5: Source/Link | Q5: Other rational | R5: Waiver deviation
A6: 1 | B6: Hypothèses Programmatiques | C6: Strategy Naratives | D6: Objectifs politiques et stratégiques | E6: Alignement sur la stratégie de l’ASC | N6: Business Case et/ou CADRE Part C onglet CM list | O6: Strategy
A7: 2 | B7: Hypothèses Programmatiques | C7: Strategy Naratives | D7: Objectifs politiques et stratégiques | E7: Contraintes gouvernementales ou directives de haut niveau | N7: Business Case et/ou CADRE Part C onglet CM list | O7: Strategy
A8: 3 | B8: Hypothèses Programmatiques | D8: Objectifs politiques et stratégiques | E8: Type de mission : Flagship, LargeSat, SmallSat, NanoSat, Hosted Payload, Data stream partnership, data stream purchase | N8: CADRE Part A | O8: CADRE Part A ou contants
A9: 4 | B9: Hypothèses Programmatiques | D9: Objectifs politiques et stratégiques | E9: Disciplines et secteur : SatCom, Astronomie, exploration spatiale,... | N9: CADRE Part A | O9: CADRE Part A
A10: 5 | B10: Hypothèses Programmatiques | D10: Objectifs politiques et stratégiques | E10: Dépendances avec d'autres projets/missions | N10: CADRE Part A | O10: CADRE Part A
A11: 6 | B11: Hypothèses Programmatiques | C11: Strategy Naratives | D11: Budget global et financement | E11: Soumission au Conseil du Tésor (TBSub) - But de l'exercice de costing : Budget Ask, Reprofiling,… Définir le nombre de TBSub + échéancier associé aux TBSub | N11: CADRE Part C onglet Stratégie contractuelle | O11: Strategy
A12: 7 | B12: Hypothèses Programmatiques | C12: Strategy Naratives | D12: Budget global et financement | E12: Enveloppe de la masse salariale | N12: CADRE Part C onglet RAM | O12: Strategy
A13: 8 | B13: Hypothèses Programmatiques | C13: Strategy Naratives | D13: Budget global et financement | E13: Enveloppe des frais de gestion et plan de voyages | N13: CADRE Part C onglet Overhead Costs | O13: Strategy
A14: 9 | B14: Hypothèses Programmatiques | C14: Costign Plan | D14: Budget global et financement | E14: Méthodologie d'établissement des coûts | N14: Plan de l’exercice d’établissement des coûts | O14: Costing Plan
A15: 10 | B15: Hypothèses Programmatiques | C15: Costign Plan | D15: Budget global et financement | E15: Note de réflexion supplémentaire | O15: Costing Plan
A16: 11 | B16: Hypothèses Programmatiques | C16: Costign Plan | D16: Budget global et financement | E16: Au moins 2 façon différentes pour chaque incluant RAM | N16: Plan de l’exercice d’établissement des coûts - Méthodologies | O16: Costing Plan
A17: 12 | B17: Hypothèses Programmatiques | C17: Costign Plan | D17: Budget global et financement | E17: Analyse de sensibilité | N17: À compléter par Finance | O17: Costing Plan
A18: 13 | B18: Hypothèses Programmatiques | C18: Costign Plan | D18: Budget global et financement | E18: Sufficiency Report or Independent Cost Estimate or Independent Cost Review | N18: À compléter par Finance | O18: Costing Plan
A19: 14 | B19: Hypothèses Programmatiques | C19: Costign Plan | D19: Budget global et financement | E19: Analogie (nearest neighboors), lesquels. | N19: Plan de l’exercice d’établissement des coûts - Méthodologies | O19: Costing Plan
A20: 15 | B20: Hypothèses Programmatiques | C20: Costign Plan | D20: Budget global et financement | E20: Analyse paramétrique (True planning, PCEC, NCIM, SEER, Compact). CER Calibration Plan. | N20: Plan de l’exercice d’établissement des coûts - Méthodologies | O20: Costing Plan
A21: 16 | B21: Hypothèses Programmatiques | C21: Costign Plan | D21: Budget global et financement | E21: Soumission de l'industrie et jugement d'expert | N21: Plan de l’exercice d’établissement des coûts - Méthodologies | O21: Costing Plan
A22: 17 | B22: Hypothèses Programmatiques | C22: Costign Plan | D22: Budget global et financement | E22: Analyse Monte Carlo (crystal ball) | N22: Plan de l’exercice d’établissement des coûts - Méthodologies | O22: Costing Plan
A23: 18 | B23: Hypothèses Programmatiques | C23: Costign Plan | D23: Budget global et financement | E23: Bottom up, qui le fait et comment | N23: Plan de l’exercice d’établissement des coûts - Méthodologies | O23: Costing Plan
A24: 19 | B24: Hypothèses Programmatiques | C24: Costign Plan | D24: Budget global et financement | E24: Learning curves | N24: RASCI = qui fait quoi. bottom up = Plan de l’exercice d’établissement des coûts | O24: Costing Plan
A25: 20 | B25: Hypothèses Programmatiques | C25: Costign Plan | D25: Budget global et financement | E25: Inducteurs de coûts princicaux | N25: CADRE Part C onglet CER & Tools | O25: Costing Plan
A26: 21 | B26: Hypothèses Programmatiques | C26: Costign Plan | D26: Budget global et financement | E26: Normalisation ( Stochométrie) - si applicable | N26: le choix de l'outil dicte CADRE part B qui collecte info pour l'analyse paramétrique | O26: Costing Plan
A27: 22 | B27: Hypothèses Programmatiques | C27: Costign Plan | D27: Budget global et financement | E27: Tracabilité - accès aux sources - répertoires normalisés -liens | N27: CADRE Part C onglet CER & Tools | O27: Costing Plan
... A42: 37 | B42: Hypothèses Financières | C42: 8. Inflation Model | D42: Indices économiques et inflation | E42: Modèle d'inflation appliqué | N42: Inflation Model dans son propre document - Oracle db ID | O42: Inflation Model
A43: 38 | B43: Hypothèses Financières | C43: 8. Economic Constants and short answers | D43: Indices économiques et inflation | E43: Année de base / Base year | O43: Constants
A44: 39 | B44: Hypothèses Financières | C44: 8. Economic Constants and short answers | D44: Indices économiques et inflation | E44: SSC 4% | N44: Financial Constants Reports - CSA-FIN-RPT-XXXX rev 3 | O44: Constants
A45: 40 | B45: Hypothèses Financières | C45: 8. Economic Constants and short answers | D45: Indices économiques et inflation | E45: PSPC 13% | N45: Financial Constants Reports - CSA-FIN-RPT-XXXX rev 3 | O45: Constants
A46: 41 | B46: Hypothèses Financières | C46: 8. Economic Constants and short answers | D46: Indices économiques et inflation | E46: Taux du Fairness Monitor | N46: Financial Constants Reports - CSA-FIN-RPT-XXXX rev 3 | O46: Constants
A47: 42 | B47: Hypothèses Financières | C47: 8. Economic Constants and short answers | D47: Taux de change | E47: Monnaies concernées et valeur de référence (CAD, USD, EUR, etc.) | N47: Financial Constants Reports - CSA-FIN-RPT-XXXX rev 3 | O47: Constants
A48: 43 | B48: Hypothèses Financières | C48: 8. Economic Constants and short answers | D48: Taux de change | E48: Seuil de variation accepté avant révision budgétaire | N48: Defined in constnats, used in risk analysis. risk reserve - Risk register | O48: Constants
A49: 44 | B49: Hypothèses Financières | C49: 8. Economic Constants and short answers | D49: Contingence et marges de sécurité | E49: Pourcentage de contingence sur le coût total du projet (p. ex. 10 à 20 %) | N49: Defined in constnats, used in risk analysis. risk register onglet. Unknown-Unknown Risk margin | O49: Constants
A50: 45 | B50: Hypothèses Financières | C50: Strategy Naratives | D50: Contingence et marges de sécurité | E50: Barème d’évaluation des risques majeurs pour justifier la marge appliquée (modèle d’analyse de risques) | N50: À définir ici | O50: Strategy | P50: Je ne comprends pas la question
A51: 46 | B51: Hypothèses Financières | C51: Procurement Plan | D51: Stratégie contractuelle, coûts de main-d’œuvre et de sous-traitance | E51: Sunk Costs Report (STDP, EOADP, Cap Demo, Stedia FAST, ESA Program, Cubesats, space hub, Pre-Phase 0 etc) | N51: CADRe part C - Expenditure plan | O51: Procurement Plan
A52: 47 | B52: Hypothèses Financières | C52: Strategy Naratives | D52: Stratégie contractuelle, coûts de main-d’œuvre et de sous-traitance | E52: Stratégie contractuel Phase 0/A - 1 / 2 contrats | N52: CADRe Part C - Procurement strategy | O52: Strategy
A53: 48 | B53: Hypothèses Financières | C53: Strategy Naratives | D53: Stratégie contractuelle, coûts de main-d’œuvre et de sous-traitance | E53: Note de réflexion supplémentaire | O53: Strategy
A54: 49 | B54: Hypothèses Financières | C54: Procurement Plan | D54: Stratégie contractuelle, coûts de main-d’œuvre et de sous-traitance | E54: Nombre de contrats et valeur approximative prévus par phase | N54: CADRe Part C - Procurement Plan (list) | O54: Procurement Plan
A55: 50 | B55: Hypothèses Financières | C55: Strategy Naratives | D55: Stratégie contractuelle, coûts de main-d’œuvre et de sous-traitance | E55: Contrats en parallèle avec des concepts différents et un down select | N55: CADRe Part C - Procurement strategy | O55: Strategy
A56: 51 | B56: Hypothèses Financières | C56: Strategy Naratives | D56: Stratégie contractuelle, coûts de main-d’œuvre et de sous-traitance | E56: Agile ou waterfall | N56: CADRe Part C - Procurement strategy | O56: Strategy
...

Sheet 4 - RAM LoE
A3: 9 - RAM LoE Inputs
A4: Why we are asking:
B5: To capture the ORCA project's Resource Allocation Matrix: every position on the team, its classification, and its Level of Effort (LoE) as a fraction of full-time equivalent (FTE) by mission phase. Rate is looked up from 'Labour Rates lookup' by Classification, and the fiscal-year \$ columns are computed self-contained on this sheet from LoE x rate x schedule-phase-month overlap (see '3 - Phase Durations'). EBP and inflation figures are illustrative placeholders.
B10: RAM Scenario ID | C10: 1
B11: Scenario Name | C11: Nominal RAM
B12: Scenario Description | C12: The baseline RAM used for ORCA's staffing plan.
B13: Rationale | C13: Derived from the ORCA instrument suite WBS/CBS and the Phase Durations schedule.
B14: Source Doc | C14: N/A - illustrative, pending confirmed CSA staffing plan
A16: Defaults | J16: Provided by PM | Q16: LoE as % of one FTE, by phase (PM input) | X16: Rates tab | Y16: FTE per fiscal year, calculated from '3 - Phase Durations' and the phase LoE on the left
A17: Row Num | B17: Agency / Dep't | C17: Team | D17: Skillset Group | E17: Skillset | F17: Title - Role | G17: Additional Labels | H17: Branch | I17: Directorate | J17: Employee Name | K17: Position No | L17: New or Existing | M17: Classification | N17: Echelon | O17: Math Model | P17: Funding Source | Q17: Phase 0 | R17: Phase A | S17: Phase B | T17: Phase C | U17: Phase D | V17: Phase E | W17: Phase F | X17: Rate ($) | Y17: 2026 | Z17: 2027 | AA17: 2028 | AB17: 2029 | AC17: 2030 | AD17: 2031 | AE17: 2032 | AF17: 2033 | AG17: 2034 | AH17: 2035 | AI17: 2036 | AJ17: 2037 | AK17: 2038 | AL17: 2039 | AM17: 2040 | AN17: 2041 | AO17: 2042 | AP17: 2043 | AQ17: 2044 | AR17: 2045 | AS17: 2046 | AT17: 2047 | AU17: 2048 | AV17: 2049 | AW17: 2050 | AX17: 2051 | AY17: 2052 | AZ17: 2053 | BA17: 2054 | BB17: 2055 | BC17: 2056 | BD17: 2057 | BE17: 2058 | BF17: 2059 | BG17: 2060 | BH17: Total (FTE-yrs)
